Workbook

Sheet Dashboard
B2: RPS PERMIT TRACKER — DASHBOARD
B3: Rappahannock Petroleum, LLC | one row per permit
B4: ="Refreshed: "&TEXT(TODAY(),"mm/dd/yyyy") -> Refreshed: 08/12/2026
B6: STATUS COUNTS | E6: THE BIG ONE
B7: Not Started | C7: =COUNTIF(Permits!$M$2:$M$300,B7) -> 9 | E7: Unknown means Hash has not pulled the electrical yet, so we still do not know whether a building or mechanical permit is coming. Once the electrical is in hand, nothing else is needed and that row flips to None - confirmed at pull. Every Unknown inside 28 days of a work date is the thing that kills a schedule. Chase those first.
B8: Submitted to Hash | C8: =COUNTIF(Permits!$M$2:$M$300,B8) -> 0
B9: Hash Submitted Confirmed | C9: =COUNTIF(Permits!$M$2:$M$300,B9) -> 0
B10: In Progress | C10: =COUNTIF(Permits!$M$2:$M$300,B10) -> 8
B11: Permit In-Hand | C11: =COUNTIF(Permits!$M$2:$M$300,B11) -> 6 | E11: WHAT EACH PERMIT IS WAITING ON
B12: Inspection Scheduled | C12: =COUNTIF(Permits!$M$2:$M$300,B12) -> 0 | E12: Permit ID | F12: Jurisdiction | G12: Pulled By | H12: Status | I12: Work Date | J12: Waiting On
B13: Complete | C13: =COUNTIF(Permits!$M$2:$M$300,B13) -> 0 | E13: 32976-ELEC | F13: Prince William County, VA | G13: Hash | H13: In Progress | I13: 46247 | J13: Confirm the USG permit was ever pulled. Work is 8/13.
B14: On Hold | C14: =COUNTIF(Permits!$M$2:$M$300,B14) -> 1 | E14: 34688-ELEC | F14: Ranson / Jefferson Co, WV | G14: Hash | H14: Not Started | I14: 46254 | J14: Hash VA license does not cover WV. Confirm before filing.
B15: Rejected | C15: =COUNTIF(Permits!$M$2:$M$300,B15) -> 1 | E15: 34022-ELEC | F15: Warren County, VA | G15: Hash | H15: In Progress | I15: 46260 | J15: Submit to inspections@warrencountyva.gov.
E16: 34022-BLDG | F16: Warren County, VA | G16: RPS | H16: Not Started | I16: 46260 | J16: RPS has not started the building permit.
B17: TOTAL PERMITS TRACKED | C17: =COUNTA(Permits!$A$2:$A$300) -> 25 | E17: 23689-ELEC | F17: Baltimore City, MD | G17: Hash | H17: On Hold | I17: 46266 | J17: Proof of ownership. Deed submitted 3/13.
E18: 32258-ELEC | F18: Warren County, VA | G18: Hash | H18: In Progress | I18: 46275 | J18: Owner signature for zoning.
B19: ATTENTION | E19: 32258-BLDG | F19: Warren County, VA | G19: RPS | H19: Not Started | I19: 46275 | J19: RPS has not started the building permit.
B20: Past due and not in hand | C20: =SUMPRODUCT((Permits!$P$2:$P$300<>"")*(Permits!$P$2:$P$300<TODAY())*(Permits!$M$2:$M$300<>"Permit In-Hand")*(Permits!$M$2:$M$300<>"Inspection Scheduled")*(Permits!$M$2:$M$300<>"Complete")) -> 5 | E20: 17206-ELEC | F20: Culpeper, VA | G20: Hash | H20: Not Started | I20: 46287 | J20: Confirm town vs county, then file.
B21: Due in the next 14 days | C21: =SUMPRODUCT((Permits!$P$2:$P$300<>"")*(Permits!$P$2:$P$300>=TODAY())*(Permits!$P$2:$P$300<=TODAY()+14)*(Permits!$M$2:$M$300<>"Permit In-Hand")) -> 3 | E21: 30479-ELEC | F21: Fairfax County, VA | G21: Hash | H21: Not Started | I21: 46289 | J21: Confirm jurisdiction, then file.
B22: Electrical not yet pulled - extras still Unknown | C22: =COUNTIF(Permits!$N$2:$N$300,"Unknown*") -> 12 | E22: 33962-ELEC | F22: Calvert County, MD | G22: Hash | H22: Rejected | J22: Find out why it was rejected before resubmitting.
B23: FIX ME: electrical in hand but still says Unknown | C23: =SUMPRODUCT((LEFT(Permits!$N$2:$N$300,7)="Unknown")*(Permits!$J$2:$J$300="Electrical")*((Permits!$M$2:$M$300="Permit In-Hand")+(Permits!$M$2:$M$300="Inspection Scheduled")+(Permits!$M$2:$M$300="Complete"))) -> 0 | E23: 33599-ELEC | F23: Fairfax County, VA | G23: Hash | H23: Not Started | J23: Work date from 7-Eleven.
B24: Electrical permits (Hash pulls) | C24: =COUNTIF(Permits!$J$2:$J$300,"Electrical") -> 22 | E24: 33714-ELEC | F24: City of Manassas Park, VA | G24: Hash | H24: Not Started | J24: File with the city, not the county.
B25: Building + Mechanical permits (RPS pulls) | C25: =COUNTIF(Permits!$K$2:$K$300,"RPS") -> 3 | E25: 36798-ELEC | F25: Loudoun County, VA | G25: Hash | H25: Not Started | J25: Confirm Loudoun vs Fairfax.
B26: No work date set yet | C26: =SUMPRODUCT((Permits!$A$2:$A$300<>"")*(Permits!$O$2:$O$300="")) -> 10 | E26: 33701-ELEC | F26: Stafford County, VA | G26: Hash | H26: In Progress | J26: Work date, then submit.
E27: 18245-ELEC | F27: Shenandoah County, VA | G27: Hash | H27: In Progress | J27: Work date, then submit.
B28: OPEN ITEMS ON THE 7/28 DRAWING SET (11 SITES) | E28: 45967-ELEC | F28: City of Harrisonburg, VA | G28: Hash | H28: In Progress | J28: Drawing final. Confirm Hash holds a City of Harrisonburg business license, then file.
B29: Page 3 General Note 1 on all eleven names Gilbarco Encore 300 as the existing unit. That belongs to 34022 only. Replace it with the generic swap note on the other ten. | E29: 24603-ELEC | F29: Henrico County, VA | G29: Hash | H29: In Progress | J29: E.C. Livingston signature, then Erin Zust pulls it.
B30: All eleven still carry 34022 data under the artwork. Only 24603 got the pixel rebuild. Rebuild before any portal upload. | E30: 24603-MECH | F30: Henrico County, VA | G30: RPS | H30: Not Started | J30: RPS has not started the mechanical permit.
B31: The 7/28 session said "four sites have diesel" but listed only three: 32258, 17206, 36798. If there is a fourth, its drawing says 3+0 and is wrong. | E31: HM-6-ELEC | F31: City of Winchester, VA | G31: Hash | H31: In Progress | J31: Value of construction and date, then upload to OpenGov.
B32: Files: Mac Studio > Permitting Apps > [site] Permit Docs, plus a combined Hash Dispenser Replacement Permit docs folder.

Sheet Permits
A1: Permit ID | B1: Site # | C1: Site Name | D1: Address | E1: City | F1: State | G1: Jurisdiction | H1: Project Type | I1: Request Type | J1: Permit Type | K1: Pulled By | L1: Requirement | M1: Status | N1: Other Permits Required | O1: Scheduled Work Date | P1: Permit Due Date | Q1: Days Until Due | R1: Submitted to Hash | S1: Hash Confirmed | T1: Submitted to Jurisdiction | U1: Permit # | V1: Fee | W1: Date Issued | X1: Inspection Date | Y1: Date Complete | Z1: Notes
A2: 33955-ELEC | B2: 33955 | C2: 7-Eleven #33955 | D2: 7489 Limestone Drive | E2: Gainesville | F2: VA | G2: Prince William County, VA | H2: Dispenser Replacement | I2: Non-PE Stamped | J2: Electrical | K2: Hash Construction | L2: Required | M2: Permit In-Hand | N2: None - confirmed at pull | O2: 46217 | P2: =IF(O2="","",O2-28) -> 46189 | Q2: =IF(P2="","",IF(OR(M2="Permit In-Hand",M2="Inspection Scheduled",M2="Complete"),"Have it",P2-TODAY())) -> Have it | Z2: Permit in hand, VA electricians confirmed. Work date 7/14 has passed - confirm the work and inspection are done and move this to Complete.
A3: 29104-ELEC | B3: 29104 | C3: 7-Eleven #29104 | D3: 11007 Nokesville Road | E3: Manassas | F3: VA | G3: Prince William County, VA | H3: Dispenser Replacement | I3: Non-PE Stamped | J3: Electrical | K3: Hash Construction | L3: Required | M3: Permit In-Hand | N3: None - confirmed at pull | O3: 46219 | P3: =IF(O3="","",O3-28) -> 46191 | Q3: =IF(P3="","",IF(OR(M3="Permit In-Hand",M3="Inspection Scheduled",M3="Complete"),"Have it",P3-TODAY())) -> Have it | Z3: Permit in hand, VA electricians confirmed. Work date 7/16 has passed - confirm the work and inspection are done and move this to Complete.
A4: 26941-ELEC | B4: 26941 | C4: 7-Eleven #26941 | D4: 15621 Jefferson Davis Highway | E4: Woodbridge | F4: VA | G4: Prince William County, VA | H4: Dispenser Replacement | I4: Non-PE Stamped | J4: Electrical | K4: Hash Construction | L4: Required | M4: Permit In-Hand | N4: None - confirmed at pull | O4: 46225 | P4: =IF(O4="","",O4-28) -> 46197 | Q4: =IF(P4="","",IF(OR(M4="Permit In-Hand",M4="Inspection Scheduled",M4="Complete"),"Have it",P4-TODAY())) -> Have it | Z4: Permit in hand, VA electricians confirmed. Work date 7/22 has passed - confirm the work and inspection are done and move this to Complete.
A5: 30484-ELEC | B5: 30484 | C5: 7-Eleven #30484 | D5: 17105 Old Stage Road | E5: Dumfries | F5: VA | G5: Prince William County, VA | H5: Dispenser Replacement | I5: Non-PE Stamped | J5: Electrical | K5: Hash Construction | L5: Required | M5: Permit In-Hand | N5: None - confirmed at pull | O5: 46231 | P5: =IF(O5="","",O5-28) -> 46203 | Q5: =IF(P5="","",IF(OR(M5="Permit In-Hand",M5="Inspection Scheduled",M5="Complete"),"Have it",P5-TODAY())) -> Have it | Z5: Permit in hand. Waiting for electricians to confirm. Work date 7/28 has passed - confirm status.
A6: 32223-ELEC | B6: 32223 | C6: 7-Eleven #32223 | D6: 6865 Wellington Rd | E6: Manassas | F6: VA | G6: Prince William County, VA | H6: Dispenser Replacement | I6: Non-PE Stamped | J6: Electrical | K6: Hash Construction | L6: Required | M6: Permit In-Hand | N6: None - confirmed at pull | O6: 46233 | P6: =IF(O6="","",O6-28) -> 46205 | Q6: =IF(P6="","",IF(OR(M6="Permit In-Hand",M6="Inspection Scheduled",M6="Complete"),"Have it",P6-TODAY())) -> Have it | Z6: Permit in hand. Waiting for electricians to confirm. Work date 7/30 has passed - confirm status.
A7: 28960-ELEC | B7: 28960 | C7: 7-Eleven #28960 | D7: 11108 Angleberger Rd | E7: Thurmont | F7: MD | G7: Frederick County, MD | H7: Dispenser Replacement | I7: Non-PE Stamped | J7: Electrical | K7: Hash Construction | L7: Required | M7: Permit In-Hand | N7: None - confirmed at pull | O7: 46280 | P7: =IF(O7="","",O7-28) -> 46252 | Q7: =IF(P7="","",IF(OR(M7="Permit In-Hand",M7="Inspection Scheduled",M7="Complete"),"Have it",P7-TODAY())) -> Have it | Z7: Permit in hand. Schedule with the canopy replacement per Paul Encinas. Work date 9/15.
A8: 32976-ELEC | B8: 32976 | C8: 7-Eleven #32976 | D8: 10438 Dumfries Road | E8: Manassas | F8: VA | G8: Prince William County, VA | H8: Dispenser Replacement | I8: Non-PE Stamped | J8: Electrical | K8: Hash Construction | L8: Required | M8: In Progress | N8: Unknown - pending Hash | O8: 46247 | P8: =IF(O8="","",O8-28) -> 46219 | Q8: =IF(P8="","",IF(OR(M8="Permit In-Hand",M8="Inspection Scheduled",M8="Complete"),"Have it",P8-TODAY())) -> -27 | Z8: MUL conversion, not a standard swap. Drawing built 7/28. USG permit status never confirmed - raised 7/28, still open. Work is 8/13 and the due date passed 27 days ago.
A9: 34688-ELEC | B9: 34688 | C9: 7-Eleven #34688 | D9: 809 N Mildred Street | E9: Ranson | F9: WV | G9: Ranson / Jefferson County, WV | H9: Dispenser Replacement | I9: Non-PE Stamped | J9: Electrical | K9: Hash Construction | L9: Required | M9: Not Started | N9: Unknown - pending Hash | O9: 46254 | P9: =IF(O9="","",O9-28) -> 46226 | Q9: =IF(P9="","",IF(OR(M9="Permit In-Hand",M9="Inspection Scheduled",M9="Complete"),"Have it",P9-TODAY())) -> -20 | Z9: WV site. Hash Class A 2705048270 is a VIRGINIA license and does not cover West Virginia. Confirm Hash can legally pull here and whether Ranson or Jefferson County issues it. Work is 8/20.
A10: 34022-ELEC | B10: 34022 | C10: 7-Eleven #34022 | D10: 251 Crooked Run Plaza | E10: Front Royal | F10: VA | G10: Warren County, VA | H10: Dispenser Replacement | I10: Non-PE Stamped | J10: Electrical | K10: Hash Construction | L10: Required | M10: In Progress | N10: Building - CONFIRMED | O10: 46260 | P10: =IF(O10="","",O10-28) -> 46232 | Q10: =IF(P10="","",IF(OR(M10="Permit In-Hand",M10="Inspection Scheduled",M10="Complete"),"Have it",P10-TODAY())) -> -14 | Z10: Application filled and flattened. MDIA form required. Email to inspections@warrencountyva.gov.
A11: 34022-BLDG | B11: 34022 | C11: 7-Eleven #34022 | D11: 251 Crooked Run Plaza | E11: Front Royal | F11: VA | G11: Warren County, VA | H11: Dispenser Replacement | I11: Non-PE Stamped | J11: Building | K11: RPS | L11: Required | M11: Not Started | O11: 46260 | P11: =IF(O11="","",O11-28) -> 46232 | Q11: =IF(P11="","",IF(OR(M11="Permit In-Hand",M11="Inspection Scheduled",M11="Complete"),"Have it",P11-TODAY())) -> -14 | Z11: Warren County requires a building permit on this one. RPS pulls it. Not started.
A12: 23689-ELEC | B12: 23689 | C12: 7-Eleven #23689 | D12: 2701 W Franklin St | E12: Baltimore | F12: MD | G12: Baltimore City, MD | H12: Dispenser Replacement | I12: Non-PE Stamped | J12: Electrical | K12: Hash Construction | L12: Required | M12: On Hold | N12: Unknown - pending Hash | O12: 46266 | P12: =IF(O12="","",O12-28) -> 46238 | Q12: =IF(P12="","",IF(OR(M12="Permit In-Hand",M12="Inspection Scheduled",M12="Complete"),"Have it",P12-TODAY())) -> -8 | Z12: No drawing built. Proof of ownership outstanding - deed submitted 3/13 and still not cleared. Baltimore City, not Baltimore County.
A13: 32258-ELEC | B13: 32258 | C13: 7-Eleven #32258 | D13: 711 S. Royal Ave | E13: Front Royal | F13: VA | G13: Warren County, VA | H13: Dispenser Replacement | I13: Non-PE Stamped | J13: Electrical | K13: Hash Construction | L13: Required | M13: In Progress | N13: Building - CONFIRMED | O13: 46275 | P13: =IF(O13="","",O13-28) -> 46247 | Q13: =IF(P13="","",IF(OR(M13="Permit In-Hand",M13="Inspection Scheduled",M13="Complete"),"Have it",P13-TODAY())) -> 1 | Z13: Application filled and flattened. Prioritize per David Arnette 6/30/26. Waiting on owner signature for zoning. MDIA form required.
A14: 32258-BLDG | B14: 32258 | C14: 7-Eleven #32258 | D14: 711 S. Royal Ave | E14: Front Royal | F14: VA | G14: Warren County, VA | H14: Dispenser Replacement | I14: Non-PE Stamped | J14: Building | K14: RPS | L14: Required | M14: Not Started | O14: 46275 | P14: =IF(O14="","",O14-28) -> 46247 | Q14: =IF(P14="","",IF(OR(M14="Permit In-Hand",M14="Inspection Scheduled",M14="Complete"),"Have it",P14-TODAY())) -> 1 | Z14: Warren County requires a building permit on this one. RPS pulls it. Not started.
A15: 17206-ELEC | B15: 17206 | C15: 7-Eleven #17206 | D15: 520 James Madison Highway | E15: Culpeper | F15: VA | G15: Culpeper County, VA | H15: Dispenser Replacement | I15: Non-PE Stamped | J15: Electrical | K15: Hash Construction | L15: Required | M15: Not Started | N15: Unknown - pending Hash | O15: 46287 | P15: =IF(O15="","",O15-28) -> 46259 | Q15: =IF(P15="","",IF(OR(M15="Permit In-Hand",M15="Inspection Scheduled",M15="Complete"),"Have it",P15-TODAY())) -> 13 | Z15: Drawing built 7/28, 3+1 diesel. Confirm Town of Culpeper vs Culpeper County before filing.
A16: 30479-ELEC | B16: 30479 | C16: 7-Eleven #30479 | D16: 6221 Rolling Road | E16: Springfield | F16: VA | G16: Fairfax County, VA | H16: Dispenser Replacement | I16: Non-PE Stamped | J16: Electrical | K16: Hash Construction | L16: Required | M16: Not Started | N16: Unknown - pending Hash | O16: 46289 | P16: =IF(O16="","",O16-28) -> 46261 | Q16: =IF(P16="","",IF(OR(M16="Permit In-Hand",M16="Inspection Scheduled",M16="Complete"),"Have it",P16-TODAY())) -> 15 | Z16: Drawing built 7/28, 3+0.
A17: 33962-ELEC | B17: 33962 | C17: 7-Eleven #33962 | D17: 3675 Hallowing Point Road | E17: Prince Frederick | F17: MD | G17: Calvert County, MD | H17: Dispenser Replacement | I17: Non-PE Stamped | J17: Electrical | K17: Hash Construction | L17: Required | M17: Rejected | N17: None - building not required | P17: =IF(O17="","",O17-28) | Q17: =IF(P17="","",IF(OR(M17="Permit In-Hand",M17="Inspection Scheduled",M17="Complete"),"Have it",P17-TODAY())) | Z17: No building permit needed, already confirmed. Electrical was rejected and must be resubmitted - find out why before resending the same package. No drawing built.
A18: 33599-ELEC | B18: 33599 | C18: 7-Eleven #33599 | D18: 14533 Lee Rd | E18: Chantilly | F18: VA | G18: Fairfax County, VA | H18: Dispenser Replacement | I18: Non-PE Stamped | J18: Electrical | K18: Hash Construction | L18: Required | M18: Not Started | N18: Unknown - pending Hash | P18: =IF(O18="","",O18-28) | Q18: =IF(P18="","",IF(OR(M18="Permit In-Hand",M18="Inspection Scheduled",M18="Complete"),"Have it",P18-TODAY())) | Z18: Drawing built 7/28, 3+0.
A19: 33714-ELEC | B19: 33714 | C19: 7-Eleven #33714 | D19: 101 Kent Village Square | E19: Manassas Park | F19: VA | G19: City of Manassas Park, VA | H19: Dispenser Replacement | I19: Non-PE Stamped | J19: Electrical | K19: Hash Construction | L19: Required | M19: Not Started | N19: Unknown - pending Hash | P19: =IF(O19="","",O19-28) | Q19: =IF(P19="","",IF(OR(M19="Permit In-Hand",M19="Inspection Scheduled",M19="Complete"),"Have it",P19-TODAY())) | Z19: Drawing built 7/28, 3+0. Independent city - files with Manassas Park, not Prince William County.
A20: 36798-ELEC | B20: 36798 | C20: 7-Eleven #36798 | D20: 25140 Loudoun County Pkwy | E20: Chantilly | F20: VA | G20: Loudoun County, VA | H20: Dispenser Replacement | I20: Non-PE Stamped | J20: Electrical | K20: Hash Construction | L20: Required | M20: Not Started | N20: Unknown - pending Hash | P20: =IF(O20="","",O20-28) | Q20: =IF(P20="","",IF(OR(M20="Permit In-Hand",M20="Inspection Scheduled",M20="Complete"),"Have it",P20-TODAY())) | Z20: Drawing built 7/28, 3+1 diesel. Confirm Loudoun vs Fairfax. Inform Paul Encinas upon completion.
A21: 33701-ELEC | B21: 33701 | C21: 7-Eleven #33701 | D21: 2998 Jefferson Davis Highway | E21: Stafford | F21: VA | G21: Stafford County, VA | H21: Dispenser Replacement | I21: Non-PE Stamped | J21: Electrical | K21: Hash Construction | L21: Required | M21: In Progress | N21: Unknown - pending Hash | P21: =IF(O21="","",O21-28) | Q21: =IF(P21="","",IF(OR(M21="Permit In-Hand",M21="Inspection Scheduled",M21="Complete"),"Have it",P21-TODAY())) | Z21: Application filled and flattened. Stafford form: Tenant = SAME AS OWNER, Applicant = SAME AS CONTRACTOR.
A22: 18245-ELEC | B22: 18245 | C22: 7-Eleven #18245 | D22: 285 W. Old Cross Rd | E22: New Market | F22: VA | G22: Shenandoah County, VA | H22: Dispenser Replacement | I22: Non-PE Stamped | J22: Electrical | K22: Hash Construction | L22: Required | M22: In Progress | N22: Unknown - pending Hash | P22: =IF(O22="","",O22-28) | Q22: =IF(P22="","",IF(OR(M22="Permit In-Hand",M22="Inspection Scheduled",M22="Complete"),"Have it",P22-TODAY())) | Z22: Application filled and flattened. One combined Shenandoah form covers all trades.
A23: 45967-ELEC | B23: 45967 | C23: Speedway #45967 | D23: 1437 S Main St | E23: Harrisonburg | F23: VA | G23: City of Harrisonburg, VA | H23: Dispenser Replacement | I23: Non-PE Stamped | J23: Electrical | K23: Hash Construction | L23: Required | M23: In Progress | N23: Unknown - pending Hash | P23: =IF(O23="","",O23-28) | Q23: =IF(P23="","",IF(OR(M23="Permit In-Hand",M23="Inspection Scheduled",M23="Complete"),"Have it",P23-TODAY())) | Z23: Drawing FINAL 8/12 - this is the new master form for dispenser drawings. Speedway brand, but 7-Eleven owns Speedway, so the owner block is the standard 7-Eleven Dallas block. Replace (6), RUL/PUL/DSL so 3+1. Harrisonburg is an independent city, NOT Rockingham County. City wants the state Class A AND a City of Harrisonburg business license number. Electrical in before 3:00 PM is usually issued same day.
A24: 24603-ELEC | B24: 24603 | C24: 7-Eleven #24603 | D24: 2111 Hilliard Rd | E24: Henrico | F24: VA | G24: Henrico County, VA | H24: Dispenser Replacement | I24: Non-PE Stamped | J24: Electrical | K24: Hash Construction | L24: Required | M24: In Progress | N24: Mechanical - CONFIRMED | P24: =IF(O24="","",O24-28) | Q24: =IF(P24="","",IF(OR(M24="Permit In-Hand",M24="Inspection Scheduled",M24="Complete"),"Have it",P24-TODAY())) | Z24: Drawing complete, Hash block, zero instances of the word new. Waiting on E.C. Livingston signature and date, then Erin Zust pulls it.
A25: 24603-MECH | B25: 24603 | C25: 7-Eleven #24603 | D25: 2111 Hilliard Rd | E25: Henrico | F25: VA | G25: Henrico County, VA | H25: Dispenser Replacement | I25: Non-PE Stamped | J25: Mechanical | K25: RPS | L25: Required | M25: Not Started | P25: =IF(O25="","",O25-28) | Q25: =IF(P25="","",IF(OR(M25="Permit In-Hand",M25="Inspection Scheduled",M25="Complete"),"Have it",P25-TODAY())) | Z25: Henrico requires a mechanical permit on this one. RPS pulls it. Not started.
A26: HM-6-ELEC | B26: HM-6 | C26: Handy Mart #6 | D26: 2605 Valley Ave | E26: Winchester | F26: VA | G26: City of Winchester, VA | H26: STP Circuit Repair | I26: Non-PE Stamped | J26: Electrical | K26: Hash Construction | L26: Required | M26: In Progress | N26: Unknown - pending Hash | P26: =IF(O26="","",O26-28) | Q26: =IF(P26="","",IF(OR(M26="Permit In-Hand",M26="Inspection Scheduled",M26="Complete"),"Have it",P26-TODAY())) | Z26: STP branch circuit repair, not a dispenser swap. Owner is H.N. Funkhouser & Co., PO Box 2038, Winchester VA 22604. Value of construction and date still blank. Upload to winchesterva.portal.opengov.com.

Sheet Workflow & Status Key
B2: HOW A PERMIT MOVES
B4: Step 1 — Request type | C4: Decide if the job needs PE stamped plans. Almost everything we do is Non-PE Stamped. When stamped plans are required, an engineering firm usually pulls the permit and we track it here anyway.
B5: Step 2 — Electrical first | C5: Every dispenser replacement starts with Hash pulling the electrical permit. Nothing else is assumed at this point.
B6: Step 3 — Discovery | C6: We find out what else the jurisdiction wants when Hash tries to pull. Some want a building permit too. Some want a mechanical. Some want neither. Until Hash reports back, the Other Permits Required column stays Unknown.
B7: Step 3a — The shortcut | C7: If the electrical permit is already in hand, nothing else is needed. Full stop. The jurisdiction would have said so at the counter. Any electrical sitting at Permit In-Hand or later gets Other Permits Required set to None - confirmed at pull, and no building or mechanical row is created.
B8: Step 4 — Split it out | C8: The moment a building or mechanical permit is confirmed, add its own row. One row per permit, never two permits on one line. RPS pulls building and mechanical. Hash pulls electrical.
B9: Step 5 — Work the ladder | C9: Each permit row moves through the status ladder below on its own. A site is not ready to work until every required permit says Permit In-Hand.
B12: STATUS LADDER
B14: Not Started | C14: Nothing sent yet.
B15: Submitted to Hash | C15: We handed the package to Hash. Hash-pulled permits only. For an RPS-pulled building or mechanical, skip to Submitted to Jurisdiction.
B16: Hash Submitted Confirmed | C16: Hash confirmed they actually filed it with the jurisdiction. Do not mark this off an assumption - get the confirmation.
B17: In Progress | C17: The jurisdiction has it and is reviewing.
B18: Permit In-Hand | C18: Permit issued and in our possession. This is the only status that clears a site to work.
B19: Inspection Scheduled | C19: Work done or scheduled and the inspection is on the calendar.
B20: Complete | C20: Inspection passed and the permit is closed out.
B21: On Hold | C21: Blocked by something outside the jurisdiction, like a missing owner signature or proof of ownership.
B22: Rejected | C22: Kicked back. Record why in Notes before resubmitting.
B25: WHO PULLS WHAT
B27: Electrical | C27: Hash Construction, Inc. Always. VA license 2705048270 Class A, exp 03/31/2027. Virginia only - it does not cover Maryland or West Virginia.
B28: Building | C28: RPS. License 2705096729 Class A, exp 01/31/2027.
B29: Mechanical | C29: RPS. Same license.
B30: PE Stamped jobs | C30: Usually the engineering firm pulls it. Track it here regardless so the site status is complete.

Sheet Jurisdiction Contacts
A1: Jurisdiction | B1: State | C1: Department | D1: Contact Name | E1: Direct Phone | F1: Email | G1: Portal / Submittal Method | H1: Turnaround | I1: Fee Notes | J1: Cheat Sheet Notes
A2: Warren County | B2: VA | C2: Building Inspections | E2: (540) 636-9973 | F2: inspections@warrencountyva.gov | G2: Digital submission by email | J2: MDIA form required with every electrical permit. BUILDING PERMIT ALSO REQUIRED on 32258 and 34022 - RPS pulls those.
A3: Henrico County | B3: VA | C3: Building Construction & Inspections | E3: (804) 501-4360 | J3: Inspections (804) 629-9782. MECHANICAL PERMIT ALSO REQUIRED on 24603 - RPS pulls it.
A4: City of Harrisonburg | B4: VA | C4: Community Development - Building Inspections, 409 S Main St 2nd Floor | E4: (540) 432-7700 | F4: permits@harrisonburgva.gov | G4: LAMA Permit Portal, email, or in person | H4: Electrical before 3 PM usually same day | I4: Based on total value of electrical work. Check payable to City of Harrisonburg. | J4: Independent city, NOT Rockingham County. Contractor must supply state Class A/B/C AND a City of Harrisonburg business license number. Portal needs a contractor registration code - call to get one.
A5: City of Winchester | B5: VA | C5: Building / Zoning, Rouss City Hall | D5: Tom Mayhew; Richie Fletcher | E5: (540) 667-1815 | G5: winchesterva.portal.opengov.com | J5: City, not Frederick County. No downloadable form - upload our own written application. MDIA (540-667-8484) is inspections only.
A6: Stafford County | B6: VA | C6: Public Works / Building Division | E6: (540) 658-8650 | J6: Tenant = SAME AS OWNER, Applicant = SAME AS CONTRACTOR.
A7: Shenandoah County | B7: VA | C7: Community Development | E7: (540) 459-6185 | J7: One combined application form covers all trades.
A8: Prince William County | B8: VA | C8: Development Services / Building Development | J8: 32976 is a MUL conversion. USG permit status unconfirmed.
A9: Loudoun County | B9: VA | C9: Planning | D9: Alex Wilkinson | E9: (703) 771-5353 | F9: Alex.Wilkinson@Loudoun.gov | J9: Confirm whether 36798 falls in Loudoun or Fairfax.
A10: Fairfax County | B10: VA | C10: Land Development Services | J10: NEEDS RESEARCH - covers 30479 and 33599.
A11: City of Manassas Park | B11: VA | C11: Building Official | J11: NEEDS RESEARCH - independent city, files separately from Prince William.
A12: Culpeper (town vs county) | B12: VA | J12: NEEDS RESEARCH - confirm which office covers 520 James Madison Hwy.
A13: Baltimore City | B13: MD | C13: Dept of Housing & Community Development | J13: NEEDS RESEARCH - proof of ownership outstanding for 23689.
A14: Calvert County | B14: MD | C14: Inspections & Permits | J14: NEEDS RESEARCH - building confirmed not required. Electrical rejected, must resubmit.
A15: Ranson / Jefferson County | B15: WV | J15: NEEDS RESEARCH - confirm issuing office and whether Hash holds a WV license.
A16: Rockingham County | B16: VA | C16: Development Center | E16: (540) 437-2354 | J16: Does NOT cover Harrisonburg addresses. Harrisonburg is an independent city.
A17: MDIA (third-party inspections) | B17: VA | C17: 3078 Shawnee Dr Ste A, Winchester VA 22601 | E17: (540) 667-8484 | J17: Inspection agency only. Does not issue permits.

Sheet Deliverables Log
A1: Date | B1: Site # | C1: Deliverable | D1: File Name | E1: Where It Lives | F1: Open Items
A2: 46231 | B2: 32976 | C2: Dispenser electrical drawing | D2: 32976 dispenser electrical drawing.pdf | E2: Mac Studio > Permitting Apps > [site] Permit Docs | F2: 3+0. FIX: page 3 General Note 1 carries 34022 Encore 300 wording. Replace with the generic swap note. 34022 residue in artwork.
A3: 46231 | B3: 34688 | C3: Dispenser electrical drawing | D3: 34688 dispenser electrical drawing.pdf | E3: Mac Studio > Permitting Apps > [site] Permit Docs | F3: 3+0. FIX: page 3 General Note 1 carries 34022 Encore 300 wording. Replace with the generic swap note. 34022 residue in artwork.
A4: 46231 | B4: 34022 | C4: Dispenser electrical drawing | D4: 34022 dispenser electrical drawing.pdf | E4: Mac Studio > Permitting Apps > [site] Permit Docs | F4: 3+0. FIX: page 3 General Note 1 carries 34022 Encore 300 wording. Replace with the generic swap note. 34022 residue in artwork.
A5: 46231 | B5: 32258 | C5: Dispenser electrical drawing | D5: 32258 dispenser electrical drawing.pdf | E5: Mac Studio > Permitting Apps > [site] Permit Docs | F5: 3+1 DSL. FIX: page 3 General Note 1 carries 34022 Encore 300 wording. Replace with the generic swap note. 34022 residue in artwork.
A6: 46231 | B6: 17206 | C6: Dispenser electrical drawing | D6: 17206 dispenser electrical drawing.pdf | E6: Mac Studio > Permitting Apps > [site] Permit Docs | F6: 3+1 DSL. FIX: page 3 General Note 1 carries 34022 Encore 300 wording. Replace with the generic swap note. 34022 residue in artwork.
A7: 46231 | B7: 30479 | C7: Dispenser electrical drawing | D7: 30479 dispenser electrical drawing.pdf | E7: Mac Studio > Permitting Apps > [site] Permit Docs | F7: 3+0. FIX: page 3 General Note 1 carries 34022 Encore 300 wording. Replace with the generic swap note. 34022 residue in artwork.
A8: 46231 | B8: 33599 | C8: Dispenser electrical drawing | D8: 33599 dispenser electrical drawing.pdf | E8: Mac Studio > Permitting Apps > [site] Permit Docs | F8: 3+0. FIX: page 3 General Note 1 carries 34022 Encore 300 wording. Replace with the generic swap note. 34022 residue in artwork.
A9: 46231 | B9: 33714 | C9: Dispenser electrical drawing | D9: 33714 dispenser electrical drawing.pdf | E9: Mac Studio > Permitting Apps > [site] Permit Docs | F9: 3+0. FIX: page 3 General Note 1 carries 34022 Encore 300 wording. Replace with the generic swap note. 34022 residue in artwork.
A10: 46231 | B10: 36798 | C10: Dispenser electrical drawing | D10: 36798 dispenser electrical drawing.pdf | E10: Mac Studio > Permitting Apps > [site] Permit Docs | F10: 3+1 DSL. FIX: page 3 General Note 1 carries 34022 Encore 300 wording. Replace with the generic swap note. 34022 residue in artwork.
A11: 46231 | B11: 33701 | C11: Dispenser electrical drawing | D11: 33701 dispenser electrical drawing.pdf | E11: Mac Studio > Permitting Apps > [site] Permit Docs | F11: 3+0. FIX: page 3 General Note 1 carries 34022 Encore 300 wording. Replace with the generic swap note. 34022 residue in artwork.
A12: 46231 | B12: 18245 | C12: Dispenser electrical drawing | D12: 18245 dispenser electrical drawing.pdf | E12: Mac Studio > Permitting Apps > [site] Permit Docs | F12: 3+0. FIX: page 3 General Note 1 carries 34022 Encore 300 wording. Replace with the generic swap note. 34022 residue in artwork.
A13: 46231 | B13: ALL | C13: Drawing template rules | D13: Dispenser electrical drawing template.md | E13: Project knowledge
A14: 46241 | B14: 24603 | C14: Dispenser electrical drawing | D14: 24603_Dispenser_Electrical_Drawing.pdf | E14: Chat download | F14: Hash block. Zero instances of the word new. Artwork rebuilt clean. Needs E.C. Livingston signature and date.
A15: 46241 | B15: - | C15: Contact directory | D15: RPS_Contact_Directory.xlsx | E15: Chat download | F15: Re-upload to look up contacts. Raw vcf not stored.
A16: 46244 | B16: HM-6 | C16: Scope narrative + 1-page application | D16: HandyMart6 scope + application PDFs | E16: Chat download | F16: Value of construction and date still blank.
A17: 46246 | B17: 45967 | C17: Dispenser replacement drawing - FINAL | D17: 45967_Dispenser_Replacement_Drawing.pdf | E17: Chat download | F17: MASTER FORM for all future dispenser drawings. All 3 pages rebuilt clean vector. 3+1. Generic General Note 1 - no existing model named. Zip added to page 1. Zero residue: no B05, no Encore 300, no 34022, no 24603, no Starsky/Dodson, no signature line, no instance of the word new.
A18: 46246 | B18: ALL | C18: Permit tracker v2 | D18: RPS_Permit_Tracker.xlsx | E18: Upload to project knowledge | F18: Source of truth. Upload the current copy at the start of every permitting chat.

Sheet Standard Info
B2: STANDARD PARTIES — USE ON EVERY APPLICATION
B4: OWNER (every 7-Eleven permit)
B5: Company | C5: 7-Eleven, Inc.
B6: Attn | C6: David Arnette
B7: Address | C7: PO Box 711, Dallas, TX 75221-0711
B8: Phone | C8: (757) 506-9329
B9: Email | C9: david.arnette@7-11.com
B10: Rule | C10: Always the Dallas PO Box. Never the job site address.
B11: Speedway sites | C11: 7-Eleven purchased Speedway, so Speedway sites use this exact same owner block. Site 45967 included.
B12: Other brands | C12: Handy Mart #6 is H.N. Funkhouser & Co., PO Box 2038, Winchester VA 22604. That is the only job on the board with a different owner.
B14: RPS — BUILDING AND MECHANICAL PERMITS
B15: Company | C15: Rappahannock Petroleum LLC
B16: Attn | C16: Starsky Dodson
B17: Address | C17: 225 Ritter Rd, Winchester, VA 22602
B18: Phone | C18: (540) 869-5033
B19: Fax | C19: (540) 869-5406
B20: License # | C20: 2705096729, Class A
B21: License Exp | C21: 01/31/2027
B22: Federal ID (EIN) | C22: 202347099
B24: HASH — ELECTRICAL PERMITS
B25: Company | C25: Hash Construction, Inc.
B26: Address | C26: 9290 W and W Industrial Rd, La Plata, MD 20646
B27: Phone | C27: (301) 870-6195
B28: Permit Technician | C28: Erin Zust — erinzust@hashconstruction.com
B29: Signing Officer | C29: E.C. Livingston — eclivingston@hashconstruction.com, x123
B30: License # | C30: 2705048270, Class A
B31: License Exp | C31: 03/31/2027
B32: Rule | C32: RPS does not appear on permits where Hash is the contractor of record.
B33: Watch | C33: That license is Virginia. It does not cover Maryland or West Virginia.
B35: DEFAULTS
B36: Request Type | C36: Non-PE Stamped unless the jurisdiction demands sealed plans.
B37: Work Type | C37: Renovation. Repair when it is a like-for-like fix.
B38: Use Group | C38: Mercantile (M). Never Business.
B39: Occupancy | C39: Convenience store with fuel sales.
B40: Permit Due Date | C40: Scheduled work date minus 28 days. Two weeks is the hard floor.
B41: Job Site Format | C41: 7-Eleven #[site number], [address], [city], ST zip
B42: State Fields | C42: Two-letter abbreviation always: VA, MD, TX.
B43: File Naming | C43: Filled permit filenames start with the site number.
B44: Seal-off Language | C44: "No work below the seal-off or shear valve" goes on dispenser replacement scopes ONLY. Never on STP, tank pad, trenching, or underground branch circuit scopes.
B45: Used Dispenser Drawings | C45: Zero instances of the word "new" anywhere in the document.
...
