Workbook

Sheet INVOICE
L2: Updated 01/25/2017
K7: INVOICE #: | M7: ='MATERIAL AND LABOR BREAKDOWN'!C7 -> 0
K8: INVOICE DATE: | M8: ='MATERIAL AND LABOR BREAKDOWN'!C6 -> 44167
K9: SR# | M9: ='MATERIAL AND LABOR BREAKDOWN'!C9 -> PROJECT FORUM
C13: CUSTOMER: | J13: LOCATION:
C14: ='MATERIAL AND LABOR BREAKDOWN'!C2 -> VIXXO | J14: STORE | K14: ='MATERIAL AND LABOR BREAKDOWN'!C3 -> SEI/Exxon #40059
J15: ADDRESS | K15: ='MATERIAL AND LABOR BREAKDOWN'!C4 -> 13825 Lee Hwy
J16: CITY,ST,ZIP | K16: ='MATERIAL AND LABOR BREAKDOWN'!C5 -> Centerville, VA 20121
C18: ATTN: | D18: ='MATERIAL AND LABOR BREAKDOWN'!C8 -> PAUL ENCINAS
B23: SCOPE OF WORK | F23: DESCRIPTION OF WORK:
B24: STP SUMPS, MOTORS, LD'S SENSORS, AND FIBERLITE MANOLES | F24: REMOVE AND REPLACE TANK TOP STP'S WITH 7-ELEVEN SPEC BRAVO FRP RETROFIT SUMPS, FE PETRO MOTORS, VAPORLESS LD'S, AND FIBERLITE FLUSHMOUNT MANHOLES. REPLACE 18" MANHOLES ON TANK TOP WITH 7-11 SPEC OPW WATERTIGHT MANHOLES DURING EXCAVATION.
B25: UDC'S, CUSTOM STAINLESS STEEL ISLANDS, AND BOLLARDS | F25: REMOVE AND REPLACE ALL EXISTING DISPENSER SUMPS ) WITH 7-ELEVEN SPEC OPW FRP UDC'S, 3'X9x13" STAINLESS STEEL ISLANDS, AND BOLLARDS ON OUTSIDE OF ISLANDS. * WILL NEED LONG ISLASNDS TO ENCOMPASS CANOPY WRAP/COLUMN.
B26: OPW FLEXWORKS PRODUCT LINES AND 10+1 SHEAR VALVES | F26: REMOVE AND REPLACE EXISTING PRODUCT LINES WITH OPW FLEXORKS DW PIPING USING 7-11 SPEC DPC COUPLINGS AND INSTALL OPW 10+1 SHEAR VALVES
B27: OPW DOUBLE WALL SPILL BUCKETS | F27: REMOVE AND REPLACE EXISTING SPILL BUCKETS WITH 7-11 SPEC OPW 3100 DW SHEAR VALVES. (3) FILL, (2) VAPOR
B28: WIRING AND SENSORS | F28: MAKE REPAIRS TO EXISTING CONDUITS USING ROB ROY AND JUNCTION MANWAY. PULL NEW DISPENSER WIRE, 7-11 CAT 6, STP WIRE, AND SENSOR WIRE. INSTALL SENSORS IN ALL SECONDARY CONTAINMENT AND UPGRADE TLS-350 ACCORDINGLY.
B29: TANKNOLOGY, MISC | F29: PURGE, CALIBRATE, START UP DISPENSERS. MEET TANKNOLOGY ONSITE TO ENSURE SMOOTH TRANSITION TO OPEN FUEL SALES.
B31: 9 - EQUIPMENT / REMOVAL & DISPOSAL / PERMIT FEE | I31: MATERIAL | J31: UNIT | K31: SERVICE RATE | L31: SERVICE TOTAL | M31: TOTAL MATERIAL & LABOR
B32: 1 | C32: ='MATERIAL AND LABOR BREAKDOWN'!C333 -> BOBCAT FOR REMOVING DISPENSERS | I32: 0 | L32: ='MATERIAL AND LABOR BREAKDOWN'!J333 -> 850 | M32: ='MATERIAL AND LABOR BREAKDOWN'!J333 -> 850
B33: 2 | C33: ='MATERIAL AND LABOR BREAKDOWN'!B334 -> BREAKER ATTACHMENT | I33: 0 | L33: ='MATERIAL AND LABOR BREAKDOWN'!J334 -> 225 | M33: =SUM(I33+L33) -> 225
B34: 3 | C34: ='MATERIAL AND LABOR BREAKDOWN'!C335 -> SUPER VAC TRUCK - EXCAVATION | I34: 0 | L34: ='MATERIAL AND LABOR BREAKDOWN'!J335 -> 2500 | M34: =SUM(I34+L34) -> 2500
B35: 4 | C35: ='MATERIAL AND LABOR BREAKDOWN'!C336 -> 16" CONCRETE SAW W/BLADE | I35: 0 | L35: ='MATERIAL AND LABOR BREAKDOWN'!J336 -> 90 | M35: =SUM(I35+L35) -> 90
B36: 5 | C36: ='MATERIAL AND LABOR BREAKDOWN'!B337 -> P185 AIR COMPRESSOR | I36: 0 | L36: ='MATERIAL AND LABOR BREAKDOWN'!J337 -> 250 | M36: ='MATERIAL AND LABOR BREAKDOWN'!J337 -> 250
B37: 6 | C37: ='MATERIAL AND LABOR BREAKDOWN'!C338 -> MINI EXCAVATOR | I37: 0 | L37: ='MATERIAL AND LABOR BREAKDOWN'!J338 -> 1150 | M37: =SUM(I37+L37) -> 1150
B38: 7 | C38: ='MATERIAL AND LABOR BREAKDOWN'!C339 -> WATER TRAILER FOR HYDRO TESTING | I38: 0 | L38: ='MATERIAL AND LABOR BREAKDOWN'!J339 -> 225 | M38: =SUM(I38+L38) -> 225
B39: 8 | C39: ='MATERIAL AND LABOR BREAKDOWN'!C340 -> CONFINED SPACE BLOWER/HEATER | I39: 0 | L39: ='MATERIAL AND LABOR BREAKDOWN'!J340 -> 175 | M39: =SUM(I39+L39) -> 175
B40: 7 | C40: ='MATERIAL AND LABOR BREAKDOWN'!C341 -> SITE FENCING - BARRICADES | I40: 0 | L40: ='MATERIAL AND LABOR BREAKDOWN'!J341 -> 225 | M40: =SUM(I40+L40) -> 225
B41: 8 | C41: ='MATERIAL AND LABOR BREAKDOWN'!C343 -> PERMIT FEE - ELECTRICAL / MECHANICAL | I41: 0 | L41: ='MATERIAL AND LABOR BREAKDOWN'!J342 -> 0 | M41: ='MATERIAL AND LABOR BREAKDOWN'!J343 -> 2000
H42: Sub Total Material: | I42: =SUM(I32:I35) -> 0 | J42: ServiceTotal: | L42: =SUM(L32:L35) -> 3665
B43: (9)REMOVAL AND DISPOSAL TOTAL: | M43: =SUM(M32:N42) -> 7690
B44: ONSITE LABOR | I44: MATERIAL | J44: LABOR HOURS | K44: LABOR RATE | L44: TOTAL LABOR | M44: TOTAL MATERIAL & LABOR
B45: 1 | C45: ='MATERIAL AND LABOR BREAKDOWN'!C305 -> TOTAL ON-SITE LABOR | I45: 0 | J45: ='MATERIAL AND LABOR BREAKDOWN'!I294 -> 1556 | K45: ='MATERIAL AND LABOR BREAKDOWN'!D285 -> 70 | L45: =SUM(J45*K45) -> 108920 | M45: ='MATERIAL AND LABOR BREAKDOWN'!J294 -> 90720
B46: 2 | C46: SERVICE COMMISSION AND START UP | I46: 0 | J46: 20 | K46: 70 | L46: =SUM(J46*K46) -> 1400 | M46: =SUM(I46+L46) -> 1400
B47: 3 | I47: 0 | L47: =SUM(J47*K47) -> 0 | M47: =SUM(I47+L47) -> 0
B48: 4 | I48: 0 | L48: =SUM(J48*K48) -> 0 | M48: =SUM(I48+L48) -> 0
B49: 5 | I49: 0 | M49: 0
B50: 6 | I50: 0 | L50: =SUM(J50*K50) -> 0 | M50: ='MATERIAL AND LABOR BREAKDOWN'!J282 -> 0
B51: 7 | C51: ='MATERIAL AND LABOR BREAKDOWN'!C269 -> CONCRETE / REBAR / BACKFILL | I51: 0 | L51: =SUM(J51*K51) -> 0 | M51: ='MATERIAL AND LABOR BREAKDOWN'!J269 -> 11875
B52: 8 | C52: MISC / DISPOSABLES / BARRELS / RAGS / THREAD SEALANT / NITROGEN | I52: 0 | L52: =SUM(J52*K52) -> 0 | M52: ='MATERIAL AND LABOR BREAKDOWN'!J358 -> 585.18
H53: Sub Total Material: | I53: 0 | L53: =SUM(L45:L52) -> 110320
M54: =SUM(M45:N53) -> 104580.18
...

Sheet MATERIAL AND LABOR BREAKDOWN
B2: CUSTOMER | C2: VIXXO
B3: SITE # | C3: SEI/Exxon #40059
B4: ADDRESS | C4: 13825 Lee Hwy
B5: CITY, STATE | C5: Centerville, VA 20121
B6: INVOICE DATE: | C6: 44167
B7: INVOICE NUMBER:
B8: PROJECT MANAGER | C8: PAUL ENCINAS
B9: SR# | C9: PROJECT FORUM
A11: 1 | B11: ELECTRICAL SUPPLY - EECO / CAPITAL TRISTATE/HOME DEPOT
B12: PART # | C12: DESCRIPTION | D12: CURRENT PRICING | H12: Freight | I12: Amount | J12: Sell Price
B13: 3/4 INCH GALV AND EXPLOSION PROOF
B14: BBDX1 | C14: 1LB DUCK SEAL | D14: 4.53 | F14: =D14*25% -> 1.1325 | G14: =F14+D14 -> 5.6625 | J14: =SUM(I14*G14) -> 0
B15: CBCHICOA19PX | C15: SEAL COMP | D15: 34.89 | F15: =D15*25% -> 8.7225 | G15: =F15+D15 -> 43.6125 | J15: =SUM(I15*G15) -> 0
B16: CBCHICOA3 | C16: 1LB SEAL COMP - CHICO | D16: 10.48 | F16: =D16*25% -> 2.62 | G16: =F16+D16 -> 13.1 | I16: 5 | J16: =SUM(I16*G16) -> 65.5
B17: CBEYS21 | C17: 3/4 FEM COND SEAL - SEAL OFF | D17: 34.64 | F17: =D17*25% -> 8.66 | G17: =F17+D17 -> 43.3 | I17: 32 | J17: =SUM(I17*G17) -> 1385.6
B18: CBGUP214 | C18: GUP214 JCT BOX - LARGE J-BOX | D18: 94.73 | F18: =D18*25% -> 23.6825 | G18: =F18+D18 -> 118.4125 | I18: 12 | J18: =SUM(I18*G18) -> 1420.95
B19: CBLBY25 | C19: 3/4 90D COND ELL - PULL 90 | D19: 26 | F19: =D19*25% -> 6.5 | G19: =F19+D19 -> 32.5 | I19: 28 | J19: =SUM(I19*G19) -> 910
B20: CBOELB2 | C20: 3/4 OELB COND BODY&CVR L-BOX | D20: 62.22 | F20: =D20*25% -> 15.555 | G20: =F20+D20 -> 77.775 | J20: =SUM(I20*G20) -> 0
B21: CBPLG2 | C21: 3/4 RECES PLUG | D21: 2.35 | F21: =D21*25% -> 0.5875 | G21: =F21+D21 -> 2.9375 | J21: =SUM(I21*G21) -> 0
B22: CBRE21 | C22: 3/4X1/2 REDUCER BUSHING | D22: 0.536 | F22: =D22*25% -> 0.134 | G22: =F22+D22 -> 0.67 | I22: 5 | J22: =SUM(I22*G22) -> 3.35
B23: CBRE32 | C23: 1X3/4 RED | D23: 2.35 | F23: =D23*25% -> 0.5875 | G23: =F23+D23 -> 2.9375 | I23: 13 | J23: =SUM(I23*G23) -> 38.1875
B24: CBUNF205 | C24: 3/4 FEM UNION | D24: 26.07 | F24: =D24*25% -> 6.5175 | G24: =F24+D24 -> 32.5875 | I24: 12 | J24: =SUM(I24*G24) -> 391.05
B25: CBUNY205 | C25: 3/4 MALE UNION | D25: 28.5 | F25: =D25*25% -> 7.125 | G25: =F25+D25 -> 35.625 | I25: 15 | J25: =SUM(I25*G25) -> 534.375
B26: CF3/4GACP | C26: 3/4XCL GALV COND NIPPLE | D26: 1.62 | F26: =D26*25% -> 0.405 | G26: =F26+D26 -> 2.025 | I26: 12 | J26: =SUM(I26*G26) -> 24.3
B27: CF3/4X2GANIP | C27: 3/4X2 GALV COND NIPPLE | D27: 1.96 | F27: =D27*25% -> 0.49 | G27: =F27+D27 -> 2.45 | I27: 12 | J27: =SUM(I27*G27) -> 29.4
B28: CF3/4X3GANIP | C28: 3/4X3 GALV COND NIPPLE | D28: 2.31 | F28: =D28*25% -> 0.5775 | G28: =F28+D28 -> 2.8875 | I28: 12 | J28: =SUM(I28*G28) -> 34.65
B29: CF3/4X4GANIP | C29: 3/4X4 GALV COND NIPPLE | D29: 2.68 | F29: =D29*25% -> 0.67 | G29: =F29+D29 -> 3.35 | I29: 12 | J29: =SUM(I29*G29) -> 40.2
B30: CF3/4X5GANIP | C30: 3/4X5 GALV COND NIPPLE | D30: 2.97 | F30: =D30*25% -> 0.7425 | G30: =F30+D30 -> 3.7125 | I30: 12 | J30: =SUM(I30*G30) -> 44.55
B31: CF3/4X6GANIP | C31: 3/4X6 GALV COND NIPPLE | D31: 3.32 | F31: =D31*25% -> 0.83 | G31: =F31+D31 -> 4.15 | I31: 12 | J31: =SUM(I31*G31) -> 49.8
B32: CF3/4X8GANIP | C32: 3/4X8GALV COND NIPPLE | D32: 4.85 | F32: =D32*25% -> 1.2125 | G32: =F32+D32 -> 6.0625 | I32: 12 | J32: =SUM(I32*G32) -> 72.75
B33: CF3/4X10GANIP | C33: 3/4X10 GALV COND NIPPLE | D33: 5.51 | F33: =D33*25% -> 1.3775 | G33: =F33+D33 -> 6.8875 | I33: 12 | J33: =SUM(I33*G33) -> 82.65
B34: CF3/4GACP | C34: 3/4" GALV COUPL | D34: 2.147 | F34: =D34*25% -> 0.53675 | G34: =F34+D34 -> 2.68375 | I34: 12 | J34: =SUM(I34*G34) -> 32.205
B35: CO3/4GA | C35: 3/4" GALVANIZED CONDUIT | D35: 13.36 | F35: =D35*25% -> 3.34 | G35: =F35+D35 -> 16.7 | J35: =SUM(I35*G35) -> 0
B36: PV3/4 | C36: 3/4" PVC CONDUIT SCH 40 | D36: 21.93 | F36: =D36*25% -> 5.4825 | G36: =F36+D36 -> 27.4125 | J36: =SUM(I36*G36) -> 0
B37: ID30071 | C37: SIZE 71B GRY WIRECONN | D37: 6.53 | F37: =D37*25% -> 1.6325 | G37: =F37+D37 -> 8.1625 | J37: =SUM(I37*G37) -> 0
B38: ID30072 | C38: SIZE 72B BLU WIRECONN | D38: 7.37 | F38: =D38*25% -> 1.8425 | G38: =F38+D38 -> 9.2125 | J38: =SUM(I38*G38) -> 0
B39: ID30073 | C39: SIZE 73B ORG WIRECONN | D39: 8.52 | F39: =D39*25% -> 2.13 | G39: =F39+D39 -> 10.65 | J39: =SUM(I39*G39) -> 0
B40: PV3/4 | C40: 3/4" PVC CONDUIT SCH 40 | D40: 21.93 | F40: =D40*25% -> 5.4825 | G40: =F40+D40 -> 27.4125 | J40: =SUM(I40*G40) -> 0
B41: PV3/4FTA | C41: 3/4" PVC FEMALE ADAPTER | D41: 0.23 | F41: =D41*25% -> 0.0575 | G41: =F41+D41 -> 0.2875 | J41: =SUM(I41*G41) -> 0
B42: THREADED CONDUIT BUSHING 3/4" | C42: THREADED CONDUIT BUSHING - 3/4 | D42: 0.55 | F42: =D42*25% -> 0.1375 | G42: =F42+D42 -> 0.6875 | I42: 32 | J42: =SUM(I42*G42) -> 22
...

Sheet Source List
A3: 7 ELEVEN # 20412 | B3: Haymarket, VA
A5: SCOPE OF WORK | B5: DESCRIPTION OF WORK:
A6: OPW FLEXWORKS PRODUCT LINES AND 10+1 SHEAR VALVES | B6: REMOVE AND REPLACE EXISTING PRODUCT LINES WITH OPW FLEXORKS DW PIPING USING 7-11 SPEC DPC COUPLINGS AND INSTALL OPW 10+1 SHEAR VALVES
A7: ENTRY FITTINGS | B7: REMOVE AND REPLACE EXISTING UDC AND STP ENTRY FITTINGS WITH BRAVO/ICON SEI SPEC ENTRY BOOTS. HYDRO TEST ALL WORK PRIOR TO START UP FOR VERIFICATION.
A8: TANKNOLOGY / MISC | B8: PURGE, CALIBRATE, START UP DISPENSERS. MEET TANKNOLOGY ONSITE TO ENSURE SMOOTH TRANSITION TO OPEN FUEL SALES.
A9: ** ALL PARTS NUMBERS ARE SUGGESTIONS AND SHOULD ALWAYS DEFAULT TO SEI SPECS
A10: OPW | B10: DESCRIPTION | C10: Units
A11: C15A-250 | B11: 1-1/2" Double Wall Primary Pipe. | C11: 2
A12: DPC-2150A | B12: 1-1/2" Double Wall "Swage" swivel coupling | C12: 24
A13: SEF-1515 | B13: 1-1/2" Elbow NPT Flexworks | C13: 4
A14: STF-1515 | B14: 1-1/2" Junction Tee Fitting - Flexworks | C14: 8
A15: TCT-2509 | B15: Test Jumper For Double Wall Coupling (Dpc Series) 9 inch | C15: 8
A16: TTT-2536 | B16: Test Tube Termination Kit For Double Wall Coupling(Dpc Series) | C16: 4
A17: SMA-1520 | B17: Male Adapter Fittings - Motor Adapter (STP) - 1-1/2"M x 2"M Flex works | C17: 4
A18: OPW-10P-0152 | B18: 10+1-1/2 Inch Double Poppet Emergency Shear Valve | C18: 12
A19: 21BV-0200 | B19: 2" Ball Valve | C19: 4
A20: NOV
A21: 50210101 | B21: PSX-20 AMERON GLUE KITS | C21: 3
A22: 2" Smith NPT | B22: 2" BELL X CAP | C22: 6
A23: Gilbarco
A24: M00703B002 | B24: U-BOLT ENCORE
A25: ICON ENTRY FITTINGS
A26: RECEIVED AT RPS

Sheet Total Receipts
A1: TOTAL RECEIPTS FOR PROJECT
