Workbook
Name EQUIPMENT: EQUIP!$A$1:$A$11
Name PARTS: 'RPS PARTS'!$A$2:$A$1368
Name PARTSCOST: 'RPS PARTS'!$A$2:$B$1368
Name RPSPARTS: PARTS!$A$2:$C$1368

Sheet HEADER LABOR AND MATERIAL
B3: CUSTOMER | C3: SEI COMPLIANCE | D3: Removed liquid from sump. Installed New Nipple, Ball Valve. Cut Line back and installed new opw Swedge fitting on product line.Made connections. Assist Tanknology with line test. Verified passing results.
B4: SITE # | C4: 38980
B5: ADDRESS | C5: 6100 Pouncey Tract Road
B6: CITY, STATE | C6: Glen Allen, VA 23059
B7: INVOICE DATE: | C7: 44788
B8: INVOICE NUMBER:
B9: PROJECT MANAGER
B10: SR#
B11: ELECTRICAL
B12: PART # | C12: DESCRIPTION | D12: CURRENT PRICING | H12: Freight | I12: Amount | J12: Sell Price
B13: 3/4 INCH GALV AND EXPLOSION PROOF
B14: BBDX1 | C14: 1LB DUCK SEAL | D14: 4.53 | F14: 4.53 | G14: 4.53 | J14: 0
B15: CBCHICOA19PX | C15: SEAL COMP | D15: 34.89 | F15: =D15*25% -> 8.7225 | G15: =F15+D15 -> 43.6125 | J15: =SUM(I15*G15) -> 0
B16: CBCHICOA3 | C16: 1LB SEAL COMP - CHICO | D16: 10.48 | F16: =D16*25% -> 2.62 | G16: =F16+D16 -> 13.1 | J16: =SUM(I16*G16) -> 0
B17: CBEYS21 | C17: 3/4 FEM COND SEAL - SEAL OFF | D17: 34.64 | F17: =D17*25% -> 8.66 | G17: =F17+D17 -> 43.3 | J17: =SUM(I17*G17) -> 0
B18: CBGUP214 | C18: GUP214 JCT BOX - LARGE J-BOX | D18: 94.73 | F18: =D18*25% -> 23.6825 | G18: =F18+D18 -> 118.4125 | J18: =SUM(I18*G18) -> 0
B19: CBLBY25 | C19: 3/4 90D COND ELL - PULL 90 | D19: 26 | F19: =D19*25% -> 6.5 | G19: =F19+D19 -> 32.5 | J19: =SUM(I19*G19) -> 0
B20: CBOELB2 | C20: 3/4 OELB COND BODY&CVR L-BOX | D20: 62.22 | F20: =D20*25% -> 15.555 | G20: =F20+D20 -> 77.775 | J20: =SUM(I20*G20) -> 0
B21: CBPLG1 | C21: 1/2 RECES PLUG | D21: 2.9 | F21: =D21*25% -> 0.725 | G21: =F21+D21 -> 3.625 | J21: =SUM(I21*G21) -> 0
B22: CBPLG2 | C22: 3/4 RECES PLUG | D22: 2.35 | F22: =D22*25% -> 0.5875 | G22: =F22+D22 -> 2.9375 | J22: =SUM(I22*G22) -> 0
B23: CBRE21 | C23: 3/4X1/2 REDUCER BUSHING | D23: 0.536 | F23: =D23*25% -> 0.134 | G23: =F23+D23 -> 0.67 | J23: =SUM(I23*G23) -> 0
B24: CBRE32 | C24: 1X3/4 RED | D24: 2.35 | F24: =D24*25% -> 0.5875 | G24: =F24+D24 -> 2.9375 | J24: =SUM(I24*G24) -> 0
B25: CBUNF205 | C25: 3/4 FEM UNION | D25: 26.07 | F25: =D25*25% -> 6.5175 | G25: =F25+D25 -> 32.5875 | J25: =SUM(I25*G25) -> 0
B26: CBUNY205 | C26: 3/4 MALE UNION | D26: 28.5 | F26: =D26*25% -> 7.125 | G26: =F26+D26 -> 35.625 | J26: =SUM(I26*G26) -> 0
... B50: 3/4 INCH ALUMINUM FLEXIBLE COND | C50: FLEXIBLE CONDUIT - 3/4" ALUM -PER FT | D50: 0.9 | F50: =D50*25% -> 0.225 | G50: =F50+D50 -> 1.125 | J50: =SUM(I50*G50) -> 0
B51: EMT 3/4 AND 1 INCH | J51: =SUM(I51*G51) -> 0
B52: 10 FOOT STICK 1" EMT | C52: EMT CONDUIT 10 FOOT - 1 INCH | D52: 14.2 | F52: =D52*25% -> 3.55 | G52: =F52+D52 -> 17.75 | J52: =SUM(I52*G52) -> 0
B53: 10 FOOT STICK 3/4" EMT | C53: 3/4 INCH 10FT STEEL EMT | D53: 8.2 | F53: =D53*25% -> 2.05 | G53: =F53+D53 -> 10.25 | J53: =SUM(I53*G53) -> 0
B54: 3/4" BOX CONNECTOR-COMPRESSION | C54: 3/4 EMT COMPRESSION J BOX CONNECTOR | D54: 1.31 | F54: =D54*25% -> 0.3275 | G54: =F54+D54 -> 1.6375 | J54: =SUM(I54*G54) -> 0
B55: 3/4" COMPRESSION COUPLING | C55: 3/4 EMT COMPRESSION COUPLING | D55: 1.5 | F55: =D55*25% -> 0.375 | G55: =F55+D55 -> 1.875 | J55: =SUM(I55*G55) -> 0
B56: 3/4" COMP COUPLING - RAIN TIGHT | C56: 3/4" RAIN TIGHT COMPRESSION COUPLING | D56: 1.35 | F56: =D56*25% -> 0.3375 | G56: =F56+D56 -> 1.6875 | J56: =SUM(I56*G56) -> 0
B57: EMT PULL 90 3/4" | C57: EMT PULL 90 - 3/4 - RAINT TIGHT | D57: 10.73 | F57: =D57*25% -> 2.6825 | G57: =F57+D57 -> 13.4125 | J57: =SUM(I57*G57) -> 0
B58: EMT 3/4 STRAP | C58: 3/4" STRAP | D58: 0.35 | F58: =D58*25% -> 0.0875 | G58: =F58+D58 -> 0.4375 | J58: =SUM(I58*G58) -> 0
B59: ORBOF7712 | C59: EMT STEEL SET SCREW COUPLING | D59: 0.21 | F59: =D59*25% -> 0.0525 | G59: =F59+D59 -> 0.2625 | J59: =SUM(I59*G59) -> 0
B60: SC500SC | C60: 1/4" BEAM CLAMP 20TPI | D60: 0.81 | F60: =D60*25% -> 0.2025 | G60: =F60+D60 -> 1.0125 | J60: =SUM(I60*G60) -> 0
B61: CF3/4EMTEL | C61: 3/4" EMT ELBOW 90DEG | D61: 2 | F61: =D61*25% -> 0.5 | G61: =F61+D61 -> 2.5 | J61: =SUM(I61*G61) -> 0
B62: SCBU502 | C62: 3/4" 105D PLASTIC BUSHING | D62: 0.1 | F62: =D62*25% -> 0.025 | G62: =F62+D62 -> 0.125 | J62: =SUM(I62*G62) -> 0
B63: 3/4" EMT SWEEP 90 | C63: 3/4" SWEEP 90 | D63: 4.57 | F63: =D63*25% -> 1.1425 | G63: =F63+D63 -> 5.7125 | J63: =SUM(I63*G63) -> 0
B64: 3PC UNION/DB/EP | C64: EXPLOSION PROOF ERICKSON | D64: 33.15 | F64: =D64*25% -> 8.2875 | G64: =F64+D64 -> 41.4375 | J64: =SUM(I64*G64) -> 0
D65: 0 | F65: 0 | G65: 0 | J65: 0
...

Sheet PARTS
A1: ITEMS | B1: DESCRIPTION | C1: Price Level 1
A2: FIL-300HS-10 | B2: 10 MIC 3/4 FILTER | C2: 9.69
A3: FIL-40510-AD | B3: SUNOCO FILTER BLUE | C3: 13.79
A4: FIL-40510W-AD | B4: PETRO CLEAR FILTER | C4: 12.38
A5: FIL-40530W-AD | B5: DIESEL FILTER 7-11 SPEC | C5: 9.8
A6: FIL-65 | B6: 70065 400HS-30 TII Filter | C6: 14.8
A7: FIL-70032 450MG | B7: 70032 FILTER | C7: 24.94
A8: FIL-70060 | B8: 400HS-10 FILTER | C8: 14.8
A9: FIL-70064 | B9: 300HS-30 TII Filter | C9: 10.62
A10: FIL-800-30 | B10: 30 MIC FILTER | C10: 22.38
A11: FIL-CC400MB-10 | B11: ETHANOL 1" FILTER | C11: 12.15
A12: FIL-PA04270013 | B12: EPSON PRINTER | C12: 870.72
A13: GIL-EN04002G015 | B13: EXXON OVERLAY RIGHT | C13: 24.67
... A1368: VDR-VR-SENSEMOUNTKIT | B1368: VR SENSE MOUNTING KIT | C1368: 31.8

Sheet RPS PARTS
A1: RPSPARTS | B1: PRICE | C1: Remarks
A2: FIL-300HS-10 - 10 MIC 3/4 FILTER | B2: 13.79
A3: FIL-40510-AD - SUNOCO FILTER BLUE | B3: 12.38
A4: FIL-40510W-AD - PETRO CLEAR FILTER | B4: 9.8
A5: FIL-40530W-AD - DIESEL FILTER 7-11 SPEC | B5: 14.8
A6: FIL-65 - 70065 400HS-30 TII Filter | B6: 24.94
A7: FIL-70032 450MG - 70032 FILTER | B7: 14.8
A8: FIL-70060 - 400HS-10 FILTER | B8: 10.62
A9: FIL-70064 - 300HS-30 TII Filter | B9: 22.38
A10: FIL-800-30 - 30 MIC FILTER | B10: 12.15
A11: FIL-CC400MB-10 - ETHANOL 1" FILTER | B11: 870.72
A12: FIL-PA04270013 - EPSON PRINTER | B12: 24.67
A13: GIL-EN04002G015 - EXXON OVERLAY RIGHT | B13: 23.55
... A1367: VDR-S704-80034FD - USB DRIVE PX60 PASSPORT | B1367: 31.8
A1368: VDR-VR-SENSEMOUNTKIT - VR SENSE MOUNTING KIT

Sheet EQUIP
A1: EQUIPMENT | B1: DESCRIPTION | C1: SERVICE RATE
A2: SKID STEER / FORKS | B2: BOBCAT FOR REMOVING DISPENSERS | C2: 725
A3: SKID STEER / EXCAVATION | B3: DEMO SKID STEER | C3: 775
A4: BREAKER ATTACHMENT | B4: BREAKER ATTACHMENT - EXCAVATION | C4: 195
A5: SCISSOR/ROUGH TERRAIN LIFT | B5: LIFT FOR CANOPY CONDUIT WORK | C5: 890
A6: CONCRETE SAW/DIAMOND BLDE | B6: 16" CONCRETE SAW W/BLADE | C6: 90
A7: P185 AIR COMPRESSOR | B7: AIR COMPRESSOR - CONDUIT CLEAR | C7: 250
A8: DROP TUBE EXTRACTOR | B8: DROP TUBE EXTRACTOR TOOL - REINFORCED TRI-POD/COME ALONG | C8: 75
A9: INTRINSIC SAFE VAC TRAILER | B9: WATER TRAILER FOR HYDRO/PUMPOVER | C9: 225
A10: INTRINSIC SAFE HEATER BLWR | B10: CONFINED SPACE BLOWER/HEATER | C10: 175
A11: SITE FENCING | B11: SITE FENCING - BARRICADES | C11: 225
