Workbook
Name EQUIPMENT: EQUIP!$A$1:$A$11
Name PARTS: #REF!
Name PARTSCOST: #REF!
Name RPSPARTS: PARTS!$A$2:$C$1368

Sheet INVOICE
M2: updated 12/16/20
K7: INVOICE #:
K8: INVOICE DATE: | M8: ='HEADER LABOR AND MATERIAL'!C6 -> 44336
K9: PROJECT FORUM: | M9: ='HEADER LABOR AND MATERIAL'!C9 -> 1-4906517332
C13: CUSTOMER: | K13: SITE LOCATION
C14: 7 ELEVEN INC | K14: STORE# | L14: ='HEADER LABOR AND MATERIAL'!C3 -> 28316
C15: PO BOX 711 | K15: ADDRESS | L15: ='HEADER LABOR AND MATERIAL'!C4 -> 49 PATRICK HENRY WAY
C16: DALLAS, TX 75221 | K16: CITY, STATE, ZIP | M16: ='HEADER LABOR AND MATERIAL'!C5 -> Charles Town
C17: CONSTRUCTION MANAGER
D18: ='HEADER LABOR AND MATERIAL'!C8 -> 0
B22: SCOPE OF WORK
C24: ELECTRICAL SUPPLIES AND MATERIALS | J24: COST | K24: UNIT | L24: SHIP | M24: SUBTOTAL | N24: ELECTRICAL
B25: 1 | C25: ELECTRICAL SUPPLIES AND MATERIALS | N25: ='HEADER LABOR AND MATERIAL'!J116 -> 0
B26: 2 | C26: DISPENSER WIRE | N26: ='HEADER LABOR AND MATERIAL'!J124 -> 0
B27: 3 | C27: CABLE/INTERCOM/CAT6/DATA WIRE | N27: ='HEADER LABOR AND MATERIAL'!J134 -> 0
B28: 4
B29: 5
B30: 6
B31: 7
B32: 8
J33: ELECTRICAL TOTAL: | N33: =SUM(N25:O32) -> 0
C34: HARD PIPING - PLUMBING SUPPLIES | J34: COST | K34: UNIT | L34: FREIGHT | M34: SUBTOTAL | N34: PIPING
B35: 1 | C35: HARD PIPING - STP/DISPENSERS/SPILL BUCKETS AND RISERS | N35: ='HEADER LABOR AND MATERIAL'!J173 -> 0
B36: 2
B37: 3
B38: 4
B39: 5
B40: 6
B41: 7
B42: 8
B43: HARD PIPING TOTAL | N43: ='HEADER LABOR AND MATERIAL'!J173 -> 0
C44: RPS PARTS SOLD | J44: COST | L44: UNIT | M44: SUBTOTAL | N44: TOTAL
B45: 1 | C45: ='HEADER LABOR AND MATERIAL'!C390 | J45: ='HEADER LABOR AND MATERIAL'!D390 -> 0 | L45: ='HEADER LABOR AND MATERIAL'!I390 -> 0 | N45: ='HEADER LABOR AND MATERIAL'!J390 -> 0
B46: 2 | C46: ='HEADER LABOR AND MATERIAL'!C391 | J46: ='HEADER LABOR AND MATERIAL'!D391 -> 0 | L46: ='HEADER LABOR AND MATERIAL'!I391 -> 0 | N46: ='HEADER LABOR AND MATERIAL'!J391 -> 0
B47: 3 | C47: ='HEADER LABOR AND MATERIAL'!C392 | J47: ='HEADER LABOR AND MATERIAL'!D392 -> 0 | L47: ='HEADER LABOR AND MATERIAL'!I392 -> 0 | N47: ='HEADER LABOR AND MATERIAL'!J392 -> 0
B48: 4 | C48: ='HEADER LABOR AND MATERIAL'!C393 | J48: ='HEADER LABOR AND MATERIAL'!D393 -> 0 | L48: ='HEADER LABOR AND MATERIAL'!I393 -> 0 | N48: ='HEADER LABOR AND MATERIAL'!J393 -> 0
B49: 5 | C49: ='HEADER LABOR AND MATERIAL'!C394 | J49: ='HEADER LABOR AND MATERIAL'!D394 -> 0 | L49: ='HEADER LABOR AND MATERIAL'!I394 -> 0 | N49: ='HEADER LABOR AND MATERIAL'!J394 -> 0
B50: 6 | C50: ='HEADER LABOR AND MATERIAL'!C395 | J50: ='HEADER LABOR AND MATERIAL'!D395 -> 0 | L50: ='HEADER LABOR AND MATERIAL'!I395 -> 0 | N50: ='HEADER LABOR AND MATERIAL'!J395 -> 0
B51: 7 | C51: ='HEADER LABOR AND MATERIAL'!C396 | J51: ='HEADER LABOR AND MATERIAL'!D396 -> 0 | L51: ='HEADER LABOR AND MATERIAL'!I396 -> 0 | N51: ='HEADER LABOR AND MATERIAL'!J396 -> 0
B52: 8 | C52: ='HEADER LABOR AND MATERIAL'!C397 | J52: ='HEADER LABOR AND MATERIAL'!D397 -> 0 | L52: ='HEADER LABOR AND MATERIAL'!I397 -> 0 | N52: ='HEADER LABOR AND MATERIAL'!J397 -> 0
...

Sheet HEADER LABOR AND MATERIAL
D1: SCOPE OF WORK
B2: CUSTOMER | C2: VIXXO
B3: SITE # | C3: 28316
B4: ADDRESS | C4: =IFERROR(VLOOKUP(C3,SITE!A1:B721,2,FALSE)," ") -> 49 PATRICK HENRY WAY
B5: CITY | C5: =IFERROR(VLOOKUP(C3,SITE!A1:C721,3,FALSE)," ") -> Charles Town
B6: INVOICE DATE: | C6: 44336
B7: INVOICE NUMBER:
B8: PROJECT MANAGER
B9: SR# | C9: 1-4906517332
B10: ELECTRICAL
B11: PART # | C11: DESCRIPTION | D11: CURRENT PRICING | H11: Freight | I11: Amount | J11: Sell Price
B12: 3/4 INCH GALV AND EXPLOSION PROOF
B13: BBDX1 | C13: 1LB DUCK SEAL | D13: 4.53 | F13: =D13*25% -> 1.1325 | G13: =F13+D13 -> 5.6625 | J13: =SUM(I13*G13) -> 0
B14: CBCHICOA19PX | C14: SEAL COMP | D14: 34.89 | F14: =D14*25% -> 8.7225 | G14: =F14+D14 -> 43.6125 | J14: =SUM(I14*G14) -> 0
B15: CBCHICOA3 | C15: 1LB SEAL COMP - CHICO | D15: 10.48 | F15: =D15*25% -> 2.62 | G15: =F15+D15 -> 13.1 | J15: =SUM(I15*G15) -> 0
B16: CBEYS21 | C16: 3/4 FEM COND SEAL - SEAL OFF | D16: 34.64 | F16: =D16*25% -> 8.66 | G16: =F16+D16 -> 43.3 | J16: =SUM(I16*G16) -> 0
B17: CBGUP214 | C17: GUP214 JCT BOX - LARGE J-BOX | D17: 94.73 | F17: =D17*25% -> 23.6825 | G17: =F17+D17 -> 118.4125 | J17: =SUM(I17*G17) -> 0
B18: CBLBY25 | C18: 3/4 90D COND ELL - PULL 90 | D18: 26 | F18: =D18*25% -> 6.5 | G18: =F18+D18 -> 32.5 | J18: =SUM(I18*G18) -> 0
B19: CBOELB2 | C19: 3/4 OELB COND BODY&CVR L-BOX | D19: 62.22 | F19: =D19*25% -> 15.555 | G19: =F19+D19 -> 77.775 | J19: =SUM(I19*G19) -> 0
B20: CBPLG2 | C20: 3/4 RECES PLUG | D20: 2.35 | F20: =D20*25% -> 0.5875 | G20: =F20+D20 -> 2.9375 | J20: =SUM(I20*G20) -> 0
B21: CBRE21 | C21: 3/4X1/2 REDUCER BUSHING | D21: 0.536 | F21: =D21*25% -> 0.134 | G21: =F21+D21 -> 0.67 | J21: =SUM(I21*G21) -> 0
B22: CBRE32 | C22: 1X3/4 RED | D22: 2.35 | F22: =D22*25% -> 0.5875 | G22: =F22+D22 -> 2.9375 | J22: =SUM(I22*G22) -> 0
B23: CBUNF205 | C23: 3/4 FEM UNION | D23: 26.07 | F23: =D23*25% -> 6.5175 | G23: =F23+D23 -> 32.5875 | J23: =SUM(I23*G23) -> 0
B24: CBUNY205 | C24: 3/4 MALE UNION | D24: 28.5 | F24: =D24*25% -> 7.125 | G24: =F24+D24 -> 35.625 | J24: =SUM(I24*G24) -> 0
... B32: CF3/4X10GANIP | C32: 3/4X10 GALV COND NIPPLE | D32: 5.51 | F32: =D32*25% -> 1.3775 | G32: =F32+D32 -> 6.8875 | J32: =SUM(I32*G32) -> 0
B33: CF3/4X12GANIP | C33: 3/4X12 GALV COND NIPPLE | D33: 4.32 | F33: =D33*25% -> 1.08 | G33: =F33+D33 -> 5.4 | I33: 0 | J33: =SUM(I33*G33) -> 0
B34: CF3/4GACP | C34: 3/4" GALV COUPL | D34: 2.147 | F34: =D34*25% -> 0.53675 | G34: =F34+D34 -> 2.68375 | J34: =SUM(I34*G34) -> 0
B35: CO3/4GA | C35: 3/4" GALVANIZED CONDUIT | D35: 13.36 | F35: =D35*25% -> 3.34 | G35: =F35+D35 -> 16.7 | J35: =SUM(I35*G35) -> 0
B36: PV3/4 | C36: 3/4" PVC CONDUIT SCH 40 | D36: 21.93 | F36: =D36*25% -> 5.4825 | G36: =F36+D36 -> 27.4125 | J36: =SUM(I36*G36) -> 0
B37: ID30071 | C37: SIZE 71B GRY WIRECONN | D37: 6.53 | F37: =D37*25% -> 1.6325 | G37: =F37+D37 -> 8.1625 | J37: =SUM(I37*G37) -> 0
B38: ID30072 | C38: SIZE 72B BLU WIRECONN | D38: 7.37 | F38: =D38*25% -> 1.8425 | G38: =F38+D38 -> 9.2125 | J38: =SUM(I38*G38) -> 0
B39: ID30073 | C39: SIZE 73B ORG WIRECONN | D39: 8.52 | F39: =D39*25% -> 2.13 | G39: =F39+D39 -> 10.65 | J39: =SUM(I39*G39) -> 0
B40: PV3/4 | C40: 3/4" PVC CONDUIT SCH 40 | D40: 21.93 | F40: =D40*25% -> 5.4825 | G40: =F40+D40 -> 27.4125 | J40: =SUM(I40*G40) -> 0
B41: PV3/4FTA | C41: 3/4" PVC FEMALE ADAPTER | D41: 0.23 | F41: =D41*25% -> 0.0575 | G41: =F41+D41 -> 0.2875 | J41: =SUM(I41*G41) -> 0
B42: THREADED CONDUIT BUSHING 3/4" | C42: THREADED CONDUIT BUSHING - 3/4 | D42: 0.55 | F42: =D42*25% -> 0.1375 | G42: =F42+D42 -> 0.6875 | J42: =SUM(I42*G42) -> 0
B43: RIGID SWEEP 90 | C43: RIGID SWEEP 90 | D43: 5.91 | F43: =D43*25% -> 1.4775 | G43: =F43+D43 -> 7.3875 | J43: =SUM(I43*G43) -> 0
B44: PVC COATED CONDUIT | C44: ROB ROY | D44: 54 | F44: =D44*25% -> 13.5 | G44: =F44+D44 -> 67.5 | J44: =SUM(I44*G44) -> 0
B45: 3/4" FLEXIBLE CONNECTOR ELBOW | C45: 3/4 FLEX CONDUIT CONNECTOR ELBOW 90 | D45: 1.39 | F45: =D45*25% -> 0.3475 | G45: =F45+D45 -> 1.7375 | J45: =SUM(I45*G45) -> 0
B46: 3/4 INCH ALUMINUM FLEXIBLE COND | C46: FLEXIBLE CONDUIT - 3/4" ALUM -PER FT | D46: 0.9 | F46: =D46*25% -> 0.225 | G46: =F46+D46 -> 1.125 | J46: =SUM(I46*G46) -> 0
B47: EMT 3/4 AND 1 INCH
...

Sheet Wire and Cable
A1: CUTHN 12G WIRE - BLACK | B1: 12 GAUGE STRANDED WIRE - BLACK 500 FT | C1: 64.81
A2: CUTHN 12G WIRE - GREEN | B2: 12 GUAGE STRANDED WIRE - GREEN 500 FT | C2: 64.81
A3: CUTHN 12G WIRE - WHITE | B3: 12 GUAGE STRANDED WIRE - WHITE 500 FT | C3: 64.81
A4: CUTHN 12G WIRE - WHITE | C4: 0
A5: 44119 | B5: SHEPHARD12G/14G WIRE | C5: 4817.51
A6: 3601218-1P STR TFFN 600V Pur-Ylw | B6: 7-11 Spec 18g Twisted "DATA WIRE" - per ft | C6: 0.18
A7: WCW7931AFEQ | B7: 7-11 Approved CAT6 Belden Equivalent-per ft | C7: 1.5
A8: X-779132-001 | B8: BELDEN 7931A -1 7-11 REQ UNTIL 4/1/20 | C8: 2.812
A9: WCW88760FEQ | B9: VEEDER ROOT WIRE - BELDEN 88760 EQ | C9: 0.59
A10: X-873280-001 | B10: 9402 BELDEN EQUAL | C10: 1996
A11: X-806609-001 DATA WIRE 12-14 TPF | B11: TEAS6S-RD-100 - Red / White - ROLL 1000' | C11: 545
A12: X-806609-002 DATA WIRE 12-14 TPF | B12: TEAS6S-BL-100 - Black / White -ROLL 1000' | C12: 545
A13: X-832902-016 4 COND INTERCOM | B13: 4 CONDUCTOR BELDEN 9402 EQ INTERCOM | C13: 1009

Sheet PUMP AND TANK
A1: 1C-3112D | B1: OPW DW Edge Bucket with Drain (Fill) | C1: 817.46
A2: 1C-3112P | B2: OPW DW Edge Bucket with Plug (Vapor) | C2: 817.46
A3: 202135-KIT | B3: OPW DW EDGE PRIMARY LINER KIT, DRAIN | C3: 584.86
A4: 202136-KIT | B4: OPW DW EDGE PRIMARY LINER KIT, PLUG | C4: 584.86
A5: 61SALP-1020-EVR | B5: 4" BRASS SWIVEL ADAPTER - FILL | C5: 212.69
A6: 61VSA-1020-EVR | B6: 4" BRASS VAPOR ADAPTER | C6: 295.85
A7: 634TT-7085-EVR | B7: 4" FILL CAP | C7: 35.5
A8: 1DK-2100-EVR | B8: DRAIN KIT | C8: 65.15
A9: 1711-7085-RVT | B9: 3" ORANGE VAPOR CAP | C9: 34.29
A10: 106N-1100 | B10: #1 Identification Marker(Manufactured by OPW Fueling Components) - Supplier Part Number 106N-1100 | C10: 38
A11: 106N-2200 | B11: #2 Identification Marker(Manufactured by OPW Fueling Components) - Supplier Part Number 106N-2200 | C11: 38
A12: 106U-0125 | B12: Unleaded Identification Marker(Manufactured by OPW Fueling Components) - Supplier Part Number 106U-0125 | C12: 38
... A16: 1TAG-3000 | B16: Identification Tag Premium For Spill Bucket Lid(Manufactured by OPW Fueling Components) - Supplier Part Number 1TAG-3000 | C16: 13.12
C17: 0
A18: 206121 | B18: FSA - EDGE BUCKET ADAPTER - SHORT | C18: 83.36
A19: 206122 | B19: FSA - EDGE BUCKET ADAPTER - TALL | C19: 110.57
A20: FSA-400S | B20: FACE SEAL ADAPTER - SHORT | C20: 65.31
A21: FSA-400 | B21: FACE SEAL ADAPTER - LONG | C21: 65.31
A22: 104A-1800WT | B22: 18" MANHOLE - WATERTIGHT | C22: 209.78
A23: 104A-1200 | B23: 12" ID CAST IRON MANHOLE | C23: 109.29
A24: 104A-1800 | B24: 18' MANHOLE | C24: 153.66
C25: 0
A26: OPW FLEXWORKS
A27: DPC-2150A | B27: 1.5" DW COUPLING (SWAGE FITTING) | C27: 108.67
A28: SBC-2150 | B28: 1.5" DW SWIVEL BOLT ON COUPLING | C28: 172.63
A29: TTT-2536 | B29: TEST TUBE TERMINATION KIT - FLEXWORKS | C29: 27.14
A30: SMA-1520 | B30: 2" X 1.5" MOTOR ADAPTER | C30: 0
C31: 0
C32: 0
C33: 0
A34: OPW
A35: 10P-0152 | B35: 1.5" 10 PLUS DP SHEAR VALVE | C35: 200.91
A36: 71SO-410C | B36: DROP TUBE W/OVERFILL VALVE 10 FOOT | C36: 736.5
A37: 61JSK-44CB | B37: JACK SCREW KIT IRON BASE | C37: 61.69
A38: 71SO-400C | B38: DROP TUBE W/OVERFILL VALVE 8 FOOT | C38: 625.74
A39: UNIVERSAL
C40: 0
A41: 303-1515 | B41: 1.5" Offset - 1.5" | C41: 38.74
A42: 303-1520 | B42: 1.5" Offset - 2" | C42: 38.74
A43: 303-1525 | B43: 1.5" Offset - 2.5" | C43: 44.08
...

Sheet ICON
A1: ISR 2.0X2.0A | B1: SPLIT REDUCER | C1: 39.6
A2: IAC IBOND50FS | B2: BONDING AGENT FAST SET | C2: 66.28
A3: IRI 3.5xplug | B3: PLUG | C3: 59.2
A4: IRI 2.4x2.0 | B4: Reducing boot | C4: 35.2
A5: IRF 4 B1.4 | B5: 4 Bolt split repair conduit boot | C5: 140
A6: IRF 4B1.0 | B6: 4 Bolt Slit Conduit Repair Boot small | C6: 140
A7: IRF 8B3.5 | B7: 8Bolt Split Flange Repair Boot | C7: 189.6
A8: IRF 8B2.5OS | B8: 8 Bolt Repair Boot - off set | C8: 189.6
A9: IRF 8B2.5 | B9: 8 bolt repair boot | C9: 189.6
A10: IRF 4B1.4NG | B10: 4 Bolt Angled Conduit Entry Boot | C10: 140
A11: IRF 8B2.0 | B11: 8 BOLT REPAIR BOOT | C11: 213.3
A12: ISR 2.5x2.5A | B12: Split Test Boot | C12: 35.2
... A35: IAC PS200 | B35: PETRO SEAL FASKET SEALANT | C35: 80.1

Sheet ELECTRICAL
A1: BBDX1 | B1: 1LB DUCK SEAL | C1: 4.53
A2: CBCHICOA19PX | B2: SEAL COMP | C2: 34.89
A3: CBCHICOA3 | B3: 1LB SEAL COMP - CHICO | C3: 10.48
A4: CBEYS21 | B4: 3/4 FEM COND SEAL - SEAL OFF | C4: 34.64
A5: CBGUP214 | B5: GUP214 JCT BOX - LARGE J-BOX | C5: 94.73
A6: CBLBY25 | B6: 3/4 90D COND ELL - PULL 90 | C6: 26
A7: CBOELB2 | B7: 3/4 OELB COND BODY&CVR L-BOX | C7: 62.22
A8: CBPLG2 | B8: 3/4 RECES PLUG | C8: 2.35
A9: CBRE21 | B9: 3/4X1/2 REDUCER BUSHING | C9: 0.536
A10: CBRE32 | B10: 1X3/4 RED | C10: 2.35
A11: CBUNF205 | B11: 3/4 FEM UNION | C11: 26.07
A12: CBUNY205 | B12: 3/4 MALE UNION | C12: 28.5
... A34: 3/4 INCH ALUMINUM FLEXIBLE COND | B34: FLEXIBLE CONDUIT - 3/4" ALUM -PER FT | C34: 0.9
A35: EMT 3/4 AND 1 INCH
A36: 10 FOOT STICK 1" EMT | B36: EMT CONDUIT 10 FOOT - 1 INCH | C36: 14.2
A37: 10 FOOT STICK 3/4" EMT | B37: 3/4 INCH 10FT STEEL EMT | C37: 8.2
A38: 3/4" BOX CONNECTOR-COMPRESSION | B38: 3/4 EMT COMPRESSION J BOX CONNECTOR | C38: 1.31
A39: 3/4" COMPRESSION COUPLING | B39: 3/4 EMT COMPRESSION COUPLING | C39: 1.5
A40: 3/4" COMP COUPLING - RAIN TIGHT | B40: 3/4" RAIN TIGHT COMPRESSION COUPLING | C40: 1.35
A41: EMT PULL 90 3/4" | B41: EMT PULL 90 - 3/4 - RAINT TIGHT | C41: 10.73
A42: EMT 3/4 STRAP | B42: 3/4" STRAP | C42: 0.35
A43: ORBOF7712 | B43: EMT STEEL SET SCREW COUPLING | C43: 0.21
A44: SC500SC | B44: 1/4" BEAM CLAMP 20TPI | C44: 0.81
A45: CF3/4EMTEL | B45: 3/4" EMT ELBOW 90DEG | C45: 2
A46: SCBU502 | B46: 3/4" 105D PLASTIC BUSHING | C46: 0.1
A47: 3/4" EMT SWEEP 90 | B47: 3/4" SWEEP 90 | C47: 4.57
A48: 3PC UNION/DB/EP | B48: EXPLOSION PROOF ERICKSON | C48: 33.15
A49: 54061312 | B49: 3/4" Rigid Conduit Locknut | C49: 0.43
C50: 0
C51: 0
A52: 1 INCH FLEXIBLE / GALVANIZED AND EXPLOSION PROOF
A53: EYS31 | B53: 1" EXPLOSION PROOF SEAL OFF | C53: 44.66
A54: UNF305 | B54: 1" STEEL FEMALE CONDUIT UNION | C54: 49.68
A55: 1" BOX CONNECT-FLEXIBLE | B55: 1" BOX CONNECTORS-FLEXIBLE | C55: 2.01
A56: 1" FLEXIBLE CONDUIT | B56: FLEXIBLE CONDUIT - 1" - 50 FOOT | C56: 92.53
A57: 1"X6" GALV NIPPLE | B57: 1"X6" GALV NIPPLE | C57: 3.47
A58: 1"XCLOSE | B58: 1" X CLOSE GALVANIZED NIPPLE | C58: 2.13
A59: 100GC | B59: 1 " GALV COUPLING | C59: 2.94
A60: 1"X2" GALV NIPPLE | B60: 1" X 2" GALVANIZED NIPPLE | C60: 2.62
A61: 1"x3" GALV NIPPLE | B61: 1"x3" GALV NIPPLE | C61: 3.25
...

Sheet FERGUSONS
C1: 0
B2: 1 " BLK ML PLUG | C2: 2.09
A3: 1 1/2 INCH
C4: 0
A5: IBNJCL | B5: 1.5"xCLOSE BLK NIPPLE | C5: 3.58
A6: IBNKM | B6: 1.5"X 3" BLK NIPPLE | C6: 5.6
B7: 1.5" X 4" BLK NIPPLE | C7: 3
B8: 1.5" X 4.5" BLK NIPPLE | C8: 4.5
B9: 1.5" x 5" BLK NIPPLE | C9: 5.89
B10: 1.5" x 5.5" BLK NIPPLE | C10: 6.81
B11: 1.5" X 6" BLK NIPPLE | C11: 7.21
B12: 1.5" X 8" BLK NIPPLE | C12: 0
B13: 1.5" X 10" BLK NIPPLE | C13: 0
B14: 1.5" X 12" BLK NIPPLE | C14: 17.65
C15: 0
C16: 0
A17: 2 INCH
C18: 0
A19: BCK | B19: 2 BLK MI 150# COUP | C19: 11.06
A20: IBNKL | B20: 2X2-1/2 BLK STL NIP | C20: 0
A21: IBNKCL | B21: 2XCLOSE BLK STL NIP | C21: 4.88
A22: IBNKL | B22: 2X2-1/2 BLK STL NIP | C22: 0
A23: IBNKR | B23: 2X4" BLK STL NIPPLE | C23: 6.77
A24: IBBKD | B24: 2X4.5" BLK STL NIPPLE | C24: 7.8
A25: IB4K | B25: 2" 45 ELBOW | C25: 15.14
A26: IB150UK | B26: 2" BLK STL UNION 150# | C26: 30.95
A27: IBTK | B27: 2" BLK STL 150# TEE | C27: 20.52
A28: IB9K | B28: 2" BLK STL 150# 90 ELBOW | C28: 14.26
C29: 0
A30: FERGUSON RECEIPT | B30: 2" GALV ELBOW | C30: 22.81
A31: 4 INCH
A32: IBCP | B32: 4" BLACK STEEL COUPLING 150# | C32: 80.26
A33: IBNP12 | B33: 4" X 12" BLK STL NIPPLE | C33: 59.41
A34: IB150UJ | B34: 4" X 5" BLK STL NIPPLE | C34: 36.06
B35: 4" X CLOSE | C35: 27.29
B36: 4" X 8" BLK STL NIPPLE | C36: 44.5
B37: 4" X 36" BLK STL NIPPLE | C37: 136.24
A38: IBNPP | B38: 4" X 4" | C38: 31.57
B39: 4" X 6" | C39: 30.96

Sheet PARTS
A1: Item ID | B1: Description | C1: Price Level 1
A2: FIL-300HS-10 | B2: 10 MIC 3/4 FILTER | C2: 9.69
A3: FIL-40510-AD | B3: SUNOCO FILTER BLUE | C3: 13.79
A4: FIL-40510W-AD | B4: PETRO CLEAR FILTER | C4: 12.38
A5: FIL-40530W-AD | B5: DIESEL FILTER 7-11 SPEC | C5: 9.8
A6: FIL-65 | B6: 70065 400HS-30 TII Filter | C6: 14.8
A7: FIL-70032 450MG | B7: 70032 FILTER | C7: 24.94
A8: FIL-70060 | B8: 400HS-10 FILTER | C8: 14.8
A9: FIL-70064 | B9: 300HS-30 TII Filter | C9: 10.62
A10: FIL-800-30 | B10: 30 MIC FILTER | C10: 22.38
A11: FIL-CC400MB-10 | B11: ETHANOL 1" FILTER | C11: 12.15
A12: FIL-PA04270013 | B12: EPSON PRINTER | C12: 870.72
A13: GIL-EN04002G015 | B13: EXXON OVERLAY RIGHT | C13: 24.67
... A1281: VDR-VR-SENSEMOUNTKIT | B1281: VR SENSE MOUNTING KIT | C1281: 31.8

Sheet EQUIP
A1: EQUIPMENT | B1: DESCRIPTION | C1: SERVICE RATE
A2: SKID STEER / FORKS | B2: BOBCAT FOR REMOVING DISPENSERS | C2: 725
A3: SKID STEER / EXCAVATION | B3: DEMO SKID STEER | C3: 775
A4: BREAKER ATTACHMENT | B4: BREAKER ATTACHMENT - EXCAVATION | C4: 195
A5: SCISSOR/ROUGH TERRAIN LIFT | B5: LIFT FOR CANOPY CONDUIT WORK | C5: 890
A6: CONCRETE SAW/DIAMOND BLDE | B6: 16" CONCRETE SAW W/BLADE | C6: 90
A7: P185 AIR COMPRESSOR | B7: AIR COMPRESSOR - CONDUIT CLEAR | C7: 250
A8: DROP TUBE EXTRACTOR | B8: DROP TUBE EXTRACTOR TOOL - REINFORCED TRI-POD/COME ALONG | C8: 75
A9: INTRINSIC SAFE VAC TRAILER | B9: WATER TRAILER FOR HYDRO/PUMPOVER | C9: 225
A10: INTRINSIC SAFE HEATER BLWR | B10: CONFINED SPACE BLOWER/HEATER | C10: 175
A11: SITE FENCING | B11: SITE FENCING - BARRICADES | C11: 225

Sheet SITE
A1: Store Number | B1: Address | C1: City | D1: State | E1: Zip Code | F1: Phone Number
A2: 10634 | B2: 7800 CENTREVILLE RD | C2: Manassas | D2: VA | E2: 201111954 | F2: (703)368-3753
A3: 10635 | B3: 10911 MAIN ST | C3: Fairfax | D3: VA | E3: 220304703 | F3: (703)359-3559
A4: 10638 | B4: 110 DRYMILL RD | C4: Leesburg | D4: VA | E4: 201752612 | F4: (703)777-6816
A5: 10643 | B5: 10008 MAIN ST | C5: Fairfax | D5: VA | E5: 220313404 | F5: (703)359-3560
A6: 10645 | B6: 537 MAPLE AV | C6: Vienna | D6: VA | E6: 221804226 | F6: (703)255-9301
A7: 10646 | B7: 8211 OLD CENTREVILLE ROAD | C7: Manassas | D7: VA | E7: 201112116 | F7: (703)368-0027
A8: 10647 | B8: 3910 UNIVERSITY DR | C8: Fairfax | D8: VA | E8: 220302507 | F8: (703)359-3561
A9: 10651 | B9: 9908 GEORGETOWN PIKE | C9: Great Falls | D9: VA | E9: 22066 | F9: (703)759-5788
A10: 10652 | B10: 427 MAPLE AVE | C10: Vienna | D10: VA | E10: 221804722 | F10: (703)255-9302
A11: 10653 | B11: 701 VANBUREN ST | C11: Herndon | D11: VA | E11: 201704722 | F11: (571)203-9618
A12: 10654 | B12: 7420 OLD CENTREVILLE ROAD | C12: Manassas | D12: VA | E12: 201111642 | F12: (703)368-7201
A13: 10656 | B13: 712 W CHURCH ST | C13: Sterling | D13: VA | E13: 201644610 | F13: (703)444-1215
... A626: 39977 | B626: 1230 WOLF ROCK DR | C626: Purcellville | D626: VA | E626: 20132 | F626: (000)000-0000
A627: 40000 | B627: 701 Bermuda Hundred Rd | C627: Chester | D627: VA | E627: 23836 | F627: 8045300170
A628: 40001 | B628: 3384 Hwy 903 | C628: Bracey | D628: VA | E628: 23919 | F628: 4346892400
A629: 40002 | B629: 402 Virginia Ave. | C629: Clarksville | D629: VA | E629: 23927 | F629: 4343742003
A630: 40003 | B630: 213 West 2Nd Street | C630: Chase City | D630: VA | E630: 23924 | F630: 4343722437
A631: 40005 | B631: 961 Temple Ave. | C631: Colonial Heights | D631: VA | E631: 23834 | F631: 8045209528
A632: 40006 | B632: 111 S. County Dr. | C632: Wakefield | D632: VA | E632: 23888 | F632: 7578993310
A633: 40007 | B633: 10031 Hull St. Road | C633: North Chesterfield | D633: VA | E633: 23236 | F633: 8046752050
A634: 40009 | B634: 2753 W. Broad St. | C634: Richmond | D634: VA | E634: 23220 | F634: (804) 213-9746
A635: 40011 | B635: 7041 Commons Plza | C635: Chesterfield | D635: VA | E635: 23832 | F635: 8047686310
A636: 40012 | B636: 4810 Forest Hill Ave. | C636: Richmond | D636: VA | E636: 23225 | F636: 8048645490
A637: 40013 | B637: 1701 East Broad St. | C637: Richmond | D637: VA | E637: 23223 | F637: 8048645309
A638: 40014 | B638: 8188 Hwy 15 P.O Box 4 | C638: Clarksville | D638: VA | E638: 23927 | F638: 4343749808
A639: 40016 | B639: 11600 Midlothian Turnpike | C639: Midlothian | D639: VA | E639: 23113 | F639: 8043788700
A640: 40017 | B640: 8601 Patterson Ave. | C640: Richmond | D640: VA | E640: 23229 | F640: 8048645378
A641: 40019 | B641: 15418 Patrick Henry Hwy | C641: Amelia Ch | D641: VA | E641: 23002 | F641: 8045617331
A642: 40020 | B642: 7009 Pole Green Road | C642: Mechanicsville | D642: VA | E642: 23116 | F642: 8045598009
A643: 40021 | B643: 12201 S. Crater Road. | C643: Petersburg | D643: VA | E643: 23805 | F643: 8047331132
A644: 40022 | B644: 9900 Chester Road | C644: Chester | D644: VA | E644: 23831 | F644: 8047688171
A645: 40023 | B645: 2320 W. Hundred Road | C645: Chester | D645: VA | E645: 23831 | F645: 8047175736
A646: 40024 | B646: 2117 Willis Road | C646: Richmond | D646: VA | E646: 23237 | F646: 8042713491
... A650: 40029 | B650: 812 England Street | C650: Ashland | D650: VA | E650: 23005 | F650: 8047984176
A651: 40030 | B651: 14600 Time Square Dr. | C651: Midlothian | D651: VA | E651: 23112 | F651: (804) 739-5942
A652: 40032 | B652: 7020 Staples Mill Road | C652: Richmond | D652: VA | E652: 23228 | F652: 8046580725
A653: 40033 | B653: 3310 Church Road | C653: Richmond | D653: VA | E653: 23233 | F653: 8042705686
A654: 40035 | B654: 1120 East Atlantic Street | C654: La Crosse | D654: VA | E654: 23950 | F654: 4347577845
A655: 40037 | B655: 280 Garrisonville Rd | C655: Stafford | D655: VA | E655: 22554 | F655: 5402889944
...
